INFO:__main__:Get urls from stories
  0%|          | 0/30 [00:00<?, ?it/s]  3%|▎         | 1/30 [00:00<00:06,  4.80it/s]  7%|▋         | 2/30 [00:00<00:08,  3.31it/s] 13%|█▎        | 4/30 [00:03<00:15,  1.67it/s] 17%|█▋        | 5/30 [00:03<00:11,  2.20it/s] 20%|██        | 6/30 [00:03<00:08,  2.69it/s] 23%|██▎       | 7/30 [00:03<00:07,  2.97it/s] 30%|███       | 9/30 [00:03<00:05,  3.95it/s] 37%|███▋      | 11/30 [00:04<00:04,  4.74it/s] 47%|████▋     | 14/30 [00:04<00:02,  6.10it/s] 53%|█████▎    | 16/30 [00:05<00:05,  2.79it/s] 57%|█████▋    | 17/30 [00:06<00:03,  3.43it/s] 60%|██████    | 18/30 [00:06<00:02,  4.21it/s] 63%|██████▎   | 19/30 [00:07<00:06,  1.79it/s] 67%|██████▋   | 20/30 [00:10<00:11,  1.18s/it] 73%|███████▎  | 22/30 [00:10<00:06,  1.15it/s] 77%|███████▋  | 23/30 [00:10<00:05,  1.39it/s] 80%|████████  | 24/30 [00:11<00:03,  1.77it/s] 83%|████████▎ | 25/30 [00:11<00:02,  2.01it/s] 87%|████████▋ | 26/30 [00:11<00:01,  2.22it/s] 93%|█████████▎| 28/30 [00:13<00:01,  1.56it/s] 97%|█████████▋| 29/30 [00:14<00:00,  1.36it/s]100%|██████████| 30/30 [00:15<00:00,  1.72it/s]
  0%|          | 0/201 [00:00<?, ?it/s]INFO:__main__:Requesting http://immersivemath.com/ila/index.html
INFO:__main__:Getting metadata for http://immersivemath.com/ila/index.html
  0%|          | 1/201 [00:02<09:28,  2.84s/it]INFO:__main__:Requesting https://openstax.org/
INFO:__main__:Getting metadata for https://openstax.org
  1%|          | 2/201 [00:04<08:01,  2.42s/it]INFO:__main__:Requesting https://open.umn.edu/opentextbooks/
INFO:__main__:Getting metadata for https://open.umn.edu/opentextbooks/
  1%|▏         | 3/201 [00:06<07:17,  2.21s/it]INFO:__main__:Requesting https://www.youtube.com/channel/UCYO_jab_esuFRV4b17AJtAw
INFO:__main__:Getting metadata for https://www.youtube.com/channel/UCYO_jab_esuFRV4b17AJtAw
  2%|▏         | 4/201 [00:09<08:15,  2.52s/it]INFO:__main__:Requesting http://abstract.ups.edu/aata/
INFO:__main__:Getting metadata for http://abstract.ups.edu/aata/
  2%|▏         | 5/201 [00:10<07:26,  2.28s/it]INFO:__main__:Requesting http://linear.pugetsound.edu/html/fcla.html
INFO:__main__:Getting metadata for http://linear.pugetsound.edu/html/fcla.html
  3%|▎         | 6/201 [00:12<06:17,  1.93s/it]INFO:__main__:Requesting http://www.math.harvard.edu/~elkies/M55a.17/index.html
INFO:__main__:Getting metadata for http://www.math.harvard.edu/~elkies/M55a.17/index.html
ERROR:__main__:Could not get metadata for http://www.math.harvard.edu/~elkies/M55a.17/index.html
Traceback (most recent call last):
  File "../_scripts/crawler/crawler.py", line 94, in _get_site_title_and_description
    description = description[:450] + '...' if len(description) > 450 else description
TypeError: object of type 'NoneType' has no len()
  3%|▎         | 7/201 [00:13<05:29,  1.70s/it]INFO:__main__:Requesting https://www.lowtechmagazine.com/2019/02/heat-your-house-with-a-water-brake-windmill.html
INFO:__main__:Getting metadata for https://www.lowtechmagazine.com/2019/02/heat-your-house-with-a-water-brake-windmill.html
  4%|▍         | 8/201 [00:13<04:26,  1.38s/it]INFO:__main__:Requesting https://www.energy.gov/eere/solar/articles/solar-radiation-basics
  4%|▍         | 9/201 [00:14<03:18,  1.04s/it]INFO:__main__:Requesting https://www.nrel.gov/gis/images/map_pv_us_january_dec2008.jpg
INFO:__main__:Getting metadata for https://www.nrel.gov/gis/images/map_pv_us_january_dec2008.jpg
ERROR:__main__:Could not get metadata for https://www.nrel.gov/gis/images/map_pv_us_january_dec2008.jpg
Traceback (most recent call last):
  File "../_scripts/crawler/crawler.py", line 94, in _get_site_title_and_description
    description = description[:450] + '...' if len(description) > 450 else description
TypeError: object of type 'NoneType' has no len()
  5%|▍         | 10/201 [00:19<07:47,  2.45s/it]INFO:__main__:Requesting https://www.nrel.gov/gis/images/map_pv_us_july_dec2008.jpg
INFO:__main__:Getting metadata for https://www.nrel.gov/gis/images/map_pv_us_july_dec2008.jpg
ERROR:__main__:Could not get metadata for https://www.nrel.gov/gis/images/map_pv_us_july_dec2008.jpg
Traceback (most recent call last):
  File "../_scripts/crawler/crawler.py", line 94, in _get_site_title_and_description
    description = description[:450] + '...' if len(description) > 450 else description
TypeError: object of type 'NoneType' has no len()
  5%|▌         | 11/201 [00:25<10:27,  3.30s/it]INFO:__main__:Requesting https://en.wikipedia.org/wiki/Mechanical_equivalent_of_heat
INFO:__main__:Getting metadata for https://en.wikipedia.org/wiki/Mechanical_equivalent_of_heat
  6%|▌         | 12/201 [00:25<08:00,  2.54s/it]INFO:__main__:Requesting https://www.youtube.com/watch?v=GjcOobt9Ef8
INFO:__main__:Getting metadata for https://www.youtube.com/watch?v=GjcOobt9Ef8
  6%|▋         | 13/201 [00:26<06:20,  2.03s/it]INFO:__main__:Requesting https://en.wikipedia.org/wiki/Vortex_tube
INFO:__main__:Getting metadata for https://en.wikipedia.org/wiki/Vortex_tube
  7%|▋         | 14/201 [00:27<05:21,  1.72s/it]INFO:__main__:Requesting https://www.lowtechmagazine.com/2013/03/the-mechanical-transmission-of-power-3-wire-ropes.html
INFO:__main__:Getting metadata for https://www.lowtechmagazine.com/2013/03/the-mechanical-transmission-of-power-3-wire-ropes.html
  7%|▋         | 15/201 [00:29<04:58,  1.61s/it]INFO:__main__:Requesting https://en.wikipedia.org/wiki/Electromigration
INFO:__main__:Getting metadata for https://en.wikipedia.org/wiki/Electromigration
  8%|▊         | 16/201 [00:30<04:42,  1.53s/it]INFO:__main__:Requesting https://en.wikipedia.org/wiki/District_heating
INFO:__main__:Getting metadata for https://en.wikipedia.org/wiki/District_heating
  8%|▊         | 17/201 [00:32<05:04,  1.65s/it]INFO:__main__:Requesting https://solar.lowtechmagazine.com/2019/02/heat-your-house-with-a-water-brake-windmill.html
INFO:__main__:Getting metadata for https://solar.lowtechmagazine.com/2019/02/heat-your-house-with-a-water-brake-windmill.html
  9%|▉         | 18/201 [00:34<05:02,  1.66s/it]INFO:__main__:Requesting https://solar.lowtechmagazine.com/about/
INFO:__main__:Getting metadata for https://solar.lowtechmagazine.com/about/
  9%|▉         | 19/201 [00:35<05:18,  1.75s/it]INFO:__main__:Requesting https://colab.research.google.com/github/JuliaTPU/XLA.jl/blob/master/examples/3_LSTM_DistributedTraining.ipynb
INFO:__main__:Getting metadata for https://colab.research.google.com/github/JuliaTPU/XLA.jl/blob/master/examples/3_LSTM_DistributedTraining.ipynb
ERROR:__main__:Could not get metadata for https://colab.research.google.com/github/JuliaTPU/XLA.jl/blob/master/examples/3_LSTM_DistributedTraining.ipynb
Traceback (most recent call last):
  File "../_scripts/crawler/crawler.py", line 94, in _get_site_title_and_description
    description = description[:450] + '...' if len(description) > 450 else description
TypeError: object of type 'NoneType' has no len()
 10%|▉         | 20/201 [00:36<03:57,  1.31s/it]INFO:__main__:Requesting https://arxiv.org/abs/1810.09868
INFO:__main__:Getting metadata for https://arxiv.org/abs/1810.09868
 10%|█         | 21/201 [00:37<03:40,  1.23s/it]INFO:__main__:Requesting https://redalemeden.com/blog/2019/we-need-chrome-no-more
INFO:__main__:Getting metadata for https://redalemeden.com/blog/2019/we-need-chrome-no-more/
 11%|█         | 22/201 [00:38<03:22,  1.13s/it]INFO:__main__:Requesting https://news.softpedia.com/news/Lead-Firebug-Developer-Joins-Google-Chrome-Team-212278.shtml
ERROR:__main__:Could not reach https://news.softpedia.com/news/Lead-Firebug-Developer-Joins-Google-Chrome-Team-212278.shtml
Traceback (most recent call last):
  File "/home/travis/virtualenv/python3.6.3/lib/python3.6/site-packages/urllib3/connection.py", line 159, in _new_conn
    (self._dns_host, self.port), self.timeout, **extra_kw)
  File "/home/travis/virtualenv/python3.6.3/lib/python3.6/site-packages/urllib3/util/connection.py", line 80, in create_connection
    raise err
  File "/home/travis/virtualenv/python3.6.3/lib/python3.6/site-packages/urllib3/util/connection.py", line 70, in create_connection
    sock.connect(sa)
socket.timeout: timed out

During handling of the above exception, another exception occurred:

Traceback (most recent call last):
  File "/home/travis/virtualenv/python3.6.3/lib/python3.6/site-packages/urllib3/connectionpool.py", line 600, in urlopen
    chunked=chunked)
  File "/home/travis/virtualenv/python3.6.3/lib/python3.6/site-packages/urllib3/connectionpool.py", line 343, in _make_request
    self._validate_conn(conn)
  File "/home/travis/virtualenv/python3.6.3/lib/python3.6/site-packages/urllib3/connectionpool.py", line 839, in _validate_conn
    conn.connect()
  File "/home/travis/virtualenv/python3.6.3/lib/python3.6/site-packages/urllib3/connection.py", line 301, in connect
    conn = self._new_conn()
  File "/home/travis/virtualenv/python3.6.3/lib/python3.6/site-packages/urllib3/connection.py", line 164, in _new_conn
    (self.host, self.timeout))
urllib3.exceptions.ConnectTimeoutError: (<urllib3.connection.VerifiedHTTPSConnection object at 0x7f7ac15f07f0>, 'Connection to news.softpedia.com timed out. (connect timeout=6)')

During handling of the above exception, another exception occurred:

Traceback (most recent call last):
  File "/home/travis/virtualenv/python3.6.3/lib/python3.6/site-packages/requests/adapters.py", line 449, in send
    timeout=timeout
  File "/home/travis/virtualenv/python3.6.3/lib/python3.6/site-packages/urllib3/connectionpool.py", line 638, in urlopen
    _stacktrace=sys.exc_info()[2])
  File "/home/travis/virtualenv/python3.6.3/lib/python3.6/site-packages/urllib3/util/retry.py", line 398, in increment
    raise MaxRetryError(_pool, url, error or ResponseError(cause))
urllib3.exceptions.MaxRetryError: HTTPSConnectionPool(host='news.softpedia.com', port=443): Max retries exceeded with url: /news/Lead-Firebug-Developer-Joins-Google-Chrome-Team-212278.shtml (Caused by ConnectTimeoutError(<urllib3.connection.VerifiedHTTPSConnection object at 0x7f7ac15f07f0>, 'Connection to news.softpedia.com timed out. (connect timeout=6)'))

During handling of the above exception, another exception occurred:

Traceback (most recent call last):
  File "../_scripts/crawler/crawler.py", line 210, in metafy_url
    response = requests.get(url, timeout=6, headers={'User-Agent': 'Mozilla/5.0'})
  File "/home/travis/virtualenv/python3.6.3/lib/python3.6/site-packages/requests/api.py", line 75, in get
    return request('get', url, params=params, **kwargs)
  File "/home/travis/virtualenv/python3.6.3/lib/python3.6/site-packages/requests/api.py", line 60, in request
    return session.request(method=method, url=url, **kwargs)
  File "/home/travis/virtualenv/python3.6.3/lib/python3.6/site-packages/requests/sessions.py", line 533, in request
    resp = self.send(prep, **send_kwargs)
  File "/home/travis/virtualenv/python3.6.3/lib/python3.6/site-packages/requests/sessions.py", line 646, in send
    r = adapter.send(request, **kwargs)
  File "/home/travis/virtualenv/python3.6.3/lib/python3.6/site-packages/requests/adapters.py", line 504, in send
    raise ConnectTimeout(e, request=request)
requests.exceptions.ConnectTimeout: HTTPSConnectionPool(host='news.softpedia.com', port=443): Max retries exceeded with url: /news/Lead-Firebug-Developer-Joins-Google-Chrome-Team-212278.shtml (Caused by ConnectTimeoutError(<urllib3.connection.VerifiedHTTPSConnection object at 0x7f7ac15f07f0>, 'Connection to news.softpedia.com timed out. (connect timeout=6)'))
 11%|█▏        | 23/201 [01:02<23:47,  8.02s/it]INFO:__main__:Requesting https://www.google.com/googlebooks/chrome/
INFO:__main__:Getting metadata for https://www.google.com/googlebooks/chrome/
 12%|█▏        | 24/201 [01:02<16:41,  5.66s/it]INFO:__main__:Requesting https://getpolarized.io/
INFO:__main__:Getting metadata for https://getpolarized.io
 12%|█▏        | 25/201 [01:02<11:57,  4.07s/it]INFO:__main__:Requesting https://imgur.com/gallery/WWZxj
INFO:__main__:Getting metadata for https://imgur.com/gallery/WWZxj
 13%|█▎        | 26/201 [01:03<08:58,  3.08s/it]INFO:__main__:Requesting https://googleblog.blogspot.com/2008/09/fresh-take-on-browser.html
INFO:__main__:Getting metadata for https://googleblog.blogspot.com/2008/09/fresh-take-on-browser.html
 13%|█▎        | 27/201 [01:03<06:28,  2.23s/it]INFO:__main__:Requesting https://en.wikipedia.org/wiki/Internet_Explorer#/media/File:Internet-explorer-usage-data.svg
INFO:__main__:Getting metadata for https://en.wikipedia.org/wiki/Internet_Explorer#/media/File:Internet-explorer-usage-data.svg
 14%|█▍        | 28/201 [01:06<06:43,  2.33s/it]INFO:__main__:Requesting http://gs.statcounter.com/browser-market-share#monthly-200901-201902
INFO:__main__:Getting metadata for http://gs.statcounter.com/browser-market-share#monthly-200901-201902
 14%|█▍        | 29/201 [01:07<05:36,  1.96s/it]INFO:__main__:Requesting https://www.cnet.com/news/google-firefox-search-deal-gives-mozilla-more-money-to-push-privacy/
INFO:__main__:Getting metadata for https://www.cnet.com/news/google-firefox-search-deal-gives-mozilla-more-money-to-push-privacy/
 15%|█▍        | 30/201 [01:13<09:09,  3.21s/it]INFO:__main__:Requesting https://pianop.ly/
INFO:__main__:Getting metadata for https://pianop.ly
ERROR:__main__:Could not get metadata for https://pianop.ly
Traceback (most recent call last):
  File "../_scripts/crawler/crawler.py", line 94, in _get_site_title_and_description
    description = description[:450] + '...' if len(description) > 450 else description
TypeError: object of type 'NoneType' has no len()
 15%|█▌        | 31/201 [01:14<07:26,  2.63s/it]INFO:__main__:Requesting https://github.com/chromium/chromium
INFO:__main__:Getting metadata for https://github.com/chromium/chromium
 16%|█▌        | 32/201 [01:15<05:59,  2.13s/it]INFO:__main__:Requesting https://github.com/mozilla/gecko-dev
INFO:__main__:Getting metadata for https://github.com/mozilla/gecko-dev
 16%|█▋        | 33/201 [01:17<05:09,  1.84s/it]INFO:__main__:Requesting https://developer.microsoft.com/en-us/windows/pwa
INFO:__main__:Getting metadata for https://developer.microsoft.com/en-us/windows/pwa
 17%|█▋        | 34/201 [01:20<06:12,  2.23s/it]INFO:__main__:Requesting https://github.com/nodejs/node-chakracore
INFO:__main__:Getting metadata for https://github.com/nodejs/node-chakracore
 17%|█▋        | 35/201 [01:21<05:22,  1.94s/it]INFO:__main__:Requesting https://github.com/Microsoft/ChakraCore/issues/5865
INFO:__main__:Getting metadata for https://github.com/Microsoft/ChakraCore/issues/5865
 18%|█▊        | 36/201 [01:24<06:13,  2.27s/it]INFO:__main__:Requesting https://www.adsoftheworld.com/media/film/google_chrome_speed_tests
INFO:__main__:Getting metadata for https://www.adsoftheworld.com/media/film/google_chrome_speed_tests
ERROR:__main__:Could not get metadata for https://www.adsoftheworld.com/media/film/google_chrome_speed_tests
Traceback (most recent call last):
  File "../_scripts/crawler/crawler.py", line 94, in _get_site_title_and_description
    description = description[:450] + '...' if len(description) > 450 else description
TypeError: object of type 'NoneType' has no len()
 18%|█▊        | 37/201 [01:25<05:23,  1.97s/it]INFO:__main__:Requesting https://en.wikipedia.org/wiki/Chromium_(web_browser)#2008
INFO:__main__:Getting metadata for https://en.wikipedia.org/wiki/Chromium_(web_browser)#2008
 19%|█▉        | 38/201 [01:28<05:41,  2.10s/it]INFO:__main__:Requesting https://www.qutebrowser.org
INFO:__main__:Getting metadata for https://www.qutebrowser.org
 19%|█▉        | 39/201 [01:31<06:20,  2.35s/it]INFO:__main__:Requesting https://arstechnica.com/information-technology/2013/04/google-going-its-own-way-forking-webkit-rendering-engine/
INFO:__main__:Getting metadata for https://arstechnica.com/information-technology/2013/04/google-going-its-own-way-forking-webkit-rendering-engine/
 20%|█▉        | 40/201 [01:31<04:44,  1.77s/it]INFO:__main__:Requesting https://blog.chromium.org/2013/04/blink-rendering-engine-for-chromium.html
INFO:__main__:Getting metadata for https://blog.chromium.org/2013/04/blink-rendering-engine-for-chromium.html
 20%|██        | 41/201 [01:31<03:35,  1.35s/it]INFO:__main__:Requesting https://support.mozilla.org/en-US/kb/containers
INFO:__main__:Getting metadata for https://support.mozilla.org/en-US/kb/containers
 21%|██        | 42/201 [01:34<04:19,  1.63s/it]INFO:__main__:Requesting https://addons.mozilla.org/en-US/firefox/addon/chrome-store-foxified/
INFO:__main__:Getting metadata for https://addons.mozilla.org/en-US/firefox/addon/chrome-store-foxified/
 21%|██▏       | 43/201 [01:35<04:03,  1.54s/it]INFO:__main__:Requesting https://support.brave.com/hc/en-us/articles/360017909112-How-can-I-add-extensions-to-Brave-
INFO:__main__:Getting metadata for https://support.brave.com/hc/en-us/articles/360017909112-How-can-I-add-extensions-to-Brave-
 22%|██▏       | 44/201 [01:36<03:17,  1.26s/it]INFO:__main__:Requesting https://hypothesis.readthedocs.io/en/latest/
INFO:__main__:Getting metadata for https://hypothesis.readthedocs.io/en/latest/
 22%|██▏       | 45/201 [01:37<03:00,  1.16s/it]INFO:__main__:Requesting https://github.com/trailofbits/deepstate
INFO:__main__:Getting metadata for https://github.com/trailofbits/deepstate
 23%|██▎       | 46/201 [01:37<02:49,  1.09s/it]INFO:__main__:Requesting https://www.gremlin.com/blog/introducing-gremlin-free/
INFO:__main__:Getting metadata for https://www.gremlin.com/blog/introducing-gremlin-free/
 23%|██▎       | 47/201 [01:39<02:48,  1.10s/it]INFO:__main__:Requesting https://www.gremlin.com/chaos-monkey/chaos-monkey-alternatives/
INFO:__main__:Getting metadata for https://www.gremlin.com/chaos-monkey/chaos-monkey-alternatives/
 24%|██▍       | 48/201 [01:40<02:56,  1.16s/it]INFO:__main__:Requesting https://www.gremlin.com/docs/infrastructure-layer/installation/
INFO:__main__:Getting metadata for https://www.gremlin.com/docs/infrastructure-layer/installation/
 24%|██▍       | 49/201 [01:41<02:52,  1.13s/it]INFO:__main__:Requesting https://www.rust-lang.org/production/users
INFO:__main__:Getting metadata for https://www.rust-lang.org/production/users
 25%|██▍       | 50/201 [01:41<02:19,  1.08it/s]INFO:__main__:Requesting https://www.gremlin.com/docs/application-layer/overview/
INFO:__main__:Getting metadata for https://www.gremlin.com/docs/application-layer/overview/
 25%|██▌       | 51/201 [01:42<02:23,  1.05it/s]INFO:__main__:Requesting http://www.apache.org/foundation/marks/faq/
INFO:__main__:Getting metadata for http://www.apache.org/foundation/marks/faq/
 26%|██▌       | 52/201 [01:43<02:05,  1.18it/s]INFO:__main__:Requesting https://www.cbsnews.com/pictures/worlds-15-ugliest-cars/7/
INFO:__main__:Getting metadata for https://www.cbsnews.com/pictures/worlds-15-ugliest-cars/7/
 26%|██▋       | 53/201 [01:43<01:43,  1.43it/s]INFO:__main__:Requesting http://gpu.rocks
INFO:__main__:Getting metadata for http://gpu.rocks
ERROR:__main__:Could not get metadata for http://gpu.rocks
Traceback (most recent call last):
  File "../_scripts/crawler/crawler.py", line 94, in _get_site_title_and_description
    description = description[:450] + '...' if len(description) > 450 else description
TypeError: object of type 'NoneType' has no len()
 27%|██▋       | 54/201 [01:44<01:22,  1.79it/s]INFO:__main__:Requesting https://github.com/gpujs/gpu.js/blob/develop/src/backend/web-gl2/fragment-shader.js#L40
INFO:__main__:Getting metadata for https://github.com/gpujs/gpu.js/blob/develop/src/backend/web-gl2/fragment-shader.js#L40
 27%|██▋       | 55/201 [01:44<01:30,  1.62it/s]INFO:__main__:Requesting https://turdnagel.com/cells/
INFO:__main__:Getting metadata for https://turdnagel.com/cells/
ERROR:__main__:Could not get metadata for https://turdnagel.com/cells/
Traceback (most recent call last):
  File "../_scripts/crawler/crawler.py", line 94, in _get_site_title_and_description
    description = description[:450] + '...' if len(description) > 450 else description
TypeError: object of type 'NoneType' has no len()
 28%|██▊       | 56/201 [01:45<01:32,  1.56it/s]INFO:__main__:Requesting https://www.zdnet.com/article/new-browser-attack-lets-hackers-run-bad-code-even-after-users-leave-a-web-page/
INFO:__main__:Getting metadata for https://www.zdnet.com/article/new-browser-attack-lets-hackers-run-bad-code-even-after-users-leave-a-web-page/
 28%|██▊       | 57/201 [01:46<01:29,  1.60it/s]INFO:__main__:Requesting https://www.bbc.com/news/world-asia-47383634
INFO:__main__:Getting metadata for https://www.bbc.com/news/world-asia-47383634
 29%|██▉       | 58/201 [01:46<01:13,  1.95it/s]INFO:__main__:Requesting https://www.secbsd.org/
INFO:__main__:Getting metadata for https://www.secbsd.org
ERROR:__main__:Could not get metadata for https://www.secbsd.org
Traceback (most recent call last):
  File "../_scripts/crawler/crawler.py", line 94, in _get_site_title_and_description
    description = description[:450] + '...' if len(description) > 450 else description
TypeError: object of type 'NoneType' has no len()
 29%|██▉       | 59/201 [01:49<03:03,  1.30s/it]INFO:__main__:Requesting https://webcache.googleusercontent.com/search?q=cache:E2OiV-7ZhGIJ:https://secbsd.org/dark-intelligence-team.html
INFO:__main__:Getting metadata for https://webcache.googleusercontent.com/search?q=cache:E2OiV-7ZhGIJ:https://secbsd.org/dark-intelligence-team.html
 30%|██▉       | 60/201 [01:54<05:48,  2.47s/it]INFO:__main__:Requesting https://longform.org/posts/the-mastermind
INFO:__main__:Getting metadata for https://longform.org/posts/the-mastermind
 30%|███       | 61/201 [01:55<04:19,  1.86s/it]INFO:__main__:Requesting https://www.gimletmedia.com/reply-all/the-founder#episode-player
INFO:__main__:Getting metadata for https://www.gimletmedia.com/reply-all/the-founder#episode-player
ERROR:__main__:Could not get metadata for https://www.gimletmedia.com/reply-all/the-founder#episode-player
Traceback (most recent call last):
  File "../_scripts/crawler/crawler.py", line 94, in _get_site_title_and_description
    description = description[:450] + '...' if len(description) > 450 else description
TypeError: object of type 'NoneType' has no len()
 31%|███       | 62/201 [01:56<03:39,  1.58s/it]INFO:__main__:Requesting https://www.youtube.com/watch?v=MTeonvkHKDk
INFO:__main__:Getting metadata for https://www.youtube.com/watch?v=MTeonvkHKDk
 31%|███▏      | 63/201 [01:56<03:09,  1.37s/it]INFO:__main__:Requesting https://www.vulture.com/amp/2019/02/michael-mann-and-elaine-shannon-talk-on-hunting-leroux.html
INFO:__main__:Getting metadata for https://www.vulture.com/amp/2019/02/michael-mann-and-elaine-shannon-talk-on-hunting-leroux.html
 32%|███▏      | 64/201 [01:57<02:22,  1.04s/it]INFO:__main__:Requesting https://techcrunch.com/2019/02/26/spacex-gets-nasas-approval-to-test-launch-crew-dragon/
ERROR:__main__:Could not reach https://techcrunch.com/2019/02/26/spacex-gets-nasas-approval-to-test-launch-crew-dragon/
Traceback (most recent call last):
  File "/home/travis/virtualenv/python3.6.3/lib/python3.6/site-packages/urllib3/connectionpool.py", line 600, in urlopen
    chunked=chunked)
  File "/home/travis/virtualenv/python3.6.3/lib/python3.6/site-packages/urllib3/connectionpool.py", line 384, in _make_request
    six.raise_from(e, None)
  File "<string>", line 2, in raise_from
  File "/home/travis/virtualenv/python3.6.3/lib/python3.6/site-packages/urllib3/connectionpool.py", line 380, in _make_request
    httplib_response = conn.getresponse()
  File "/opt/python/3.6.3/lib/python3.6/http/client.py", line 1331, in getresponse
    response.begin()
  File "/opt/python/3.6.3/lib/python3.6/http/client.py", line 297, in begin
    version, status, reason = self._read_status()
  File "/opt/python/3.6.3/lib/python3.6/http/client.py", line 266, in _read_status
    raise RemoteDisconnected("Remote end closed connection without"
http.client.RemoteDisconnected: Remote end closed connection without response

During handling of the above exception, another exception occurred:

Traceback (most recent call last):
  File "/home/travis/virtualenv/python3.6.3/lib/python3.6/site-packages/requests/adapters.py", line 449, in send
    timeout=timeout
  File "/home/travis/virtualenv/python3.6.3/lib/python3.6/site-packages/urllib3/connectionpool.py", line 638, in urlopen
    _stacktrace=sys.exc_info()[2])
  File "/home/travis/virtualenv/python3.6.3/lib/python3.6/site-packages/urllib3/util/retry.py", line 367, in increment
    raise six.reraise(type(error), error, _stacktrace)
  File "/home/travis/virtualenv/python3.6.3/lib/python3.6/site-packages/urllib3/packages/six.py", line 685, in reraise
    raise value.with_traceback(tb)
  File "/home/travis/virtualenv/python3.6.3/lib/python3.6/site-packages/urllib3/connectionpool.py", line 600, in urlopen
    chunked=chunked)
  File "/home/travis/virtualenv/python3.6.3/lib/python3.6/site-packages/urllib3/connectionpool.py", line 384, in _make_request
    six.raise_from(e, None)
  File "<string>", line 2, in raise_from
  File "/home/travis/virtualenv/python3.6.3/lib/python3.6/site-packages/urllib3/connectionpool.py", line 380, in _make_request
    httplib_response = conn.getresponse()
  File "/opt/python/3.6.3/lib/python3.6/http/client.py", line 1331, in getresponse
    response.begin()
  File "/opt/python/3.6.3/lib/python3.6/http/client.py", line 297, in begin
    version, status, reason = self._read_status()
  File "/opt/python/3.6.3/lib/python3.6/http/client.py", line 266, in _read_status
    raise RemoteDisconnected("Remote end closed connection without"
urllib3.exceptions.ProtocolError: ('Connection aborted.', RemoteDisconnected('Remote end closed connection without response',))

During handling of the above exception, another exception occurred:

Traceback (most recent call last):
  File "../_scripts/crawler/crawler.py", line 210, in metafy_url
    response = requests.get(url, timeout=6, headers={'User-Agent': 'Mozilla/5.0'})
  File "/home/travis/virtualenv/python3.6.3/lib/python3.6/site-packages/requests/api.py", line 75, in get
    return request('get', url, params=params, **kwargs)
  File "/home/travis/virtualenv/python3.6.3/lib/python3.6/site-packages/requests/api.py", line 60, in request
    return session.request(method=method, url=url, **kwargs)
  File "/home/travis/virtualenv/python3.6.3/lib/python3.6/site-packages/requests/sessions.py", line 533, in request
    resp = self.send(prep, **send_kwargs)
  File "/home/travis/virtualenv/python3.6.3/lib/python3.6/site-packages/requests/sessions.py", line 646, in send
    r = adapter.send(request, **kwargs)
  File "/home/travis/virtualenv/python3.6.3/lib/python3.6/site-packages/requests/adapters.py", line 498, in send
    raise ConnectionError(err, request=request)
requests.exceptions.ConnectionError: ('Connection aborted.', RemoteDisconnected('Remote end closed connection without response',))
 32%|███▏      | 65/201 [01:57<01:44,  1.30it/s]INFO:__main__:Requesting http://exportcompliancesolutions.com/blog/2018/09/20/u-s-persons-include-just-citizens/
INFO:__main__:Getting metadata for http://exportcompliancesolutions.com/blog/2018/09/20/u-s-persons-include-just-citizens/
 33%|███▎      | 66/201 [01:57<01:25,  1.58it/s]INFO:__main__:Requesting https://www.nasaspaceflight.com/2019/02/spacex-gains-frr-green-light-dm-1-iss/
INFO:__main__:Getting metadata for https://www.nasaspaceflight.com/2019/02/spacex-gains-frr-green-light-dm-1-iss/
 33%|███▎      | 67/201 [01:58<01:32,  1.45it/s]INFO:__main__:Requesting https://outline.com/LqnKkg
INFO:__main__:Getting metadata for https://outline.com/LqnKkg
 34%|███▍      | 68/201 [01:59<01:55,  1.16it/s]INFO:__main__:Requesting https://www.sfchronicle.com/bayarea/article/In-search-of-ET-Fear-of-what-s-out-there-has-13640953.php
INFO:__main__:Getting metadata for https://www.sfchronicle.com/bayarea/article/In-search-of-ET-Fear-of-what-s-out-there-has-13640953.php
 34%|███▍      | 69/201 [02:00<01:45,  1.26it/s]INFO:__main__:Requesting https://www.newyorker.com/magazine/2019/03/04/how-much-a-dementia-patient-needs-to-know
INFO:__main__:Getting metadata for https://www.newyorker.com/magazine/2019/03/04/how-much-a-dementia-patient-needs-to-know
 35%|███▍      | 70/201 [02:00<01:26,  1.51it/s]INFO:__main__:Requesting https://gizmodo.com/inside-an-amazing-village-designed-just-for-people-with-1526062373
INFO:__main__:Getting metadata for https://gizmodo.com/inside-an-amazing-village-designed-just-for-people-with-1526062373
 35%|███▌      | 71/201 [02:01<01:10,  1.84it/s]INFO:__main__:Requesting https://cacm.acm.org/magazines/2019/3/234913-lost-in-math/fulltext
INFO:__main__:Getting metadata for https://cacm.acm.org/magazines/2019/3/234913-lost-in-math/fulltext
 36%|███▌      | 72/201 [02:08<05:29,  2.56s/it]INFO:__main__:Requesting http://www.cs.utexas.edu/users/EWD/transcriptions/EWD12xx/EWD1243a.html
INFO:__main__:Getting metadata for http://www.cs.utexas.edu/users/EWD/transcriptions/EWD12xx/EWD1243a.html
 36%|███▋      | 73/201 [02:08<04:02,  1.89s/it]INFO:__main__:Requesting https://k3s.io
INFO:__main__:Getting metadata for https://k3s.io
 37%|███▋      | 74/201 [02:09<03:12,  1.52s/it]INFO:__main__:Requesting https://fosdem.org/2019/schedule/event/hw_gitlab_ci_arduino/
INFO:__main__:Getting metadata for https://fosdem.org/2019/schedule/event/hw_gitlab_ci_arduino/
ERROR:__main__:Could not get metadata for https://fosdem.org/2019/schedule/event/hw_gitlab_ci_arduino/
Traceback (most recent call last):
  File "../_scripts/crawler/crawler.py", line 94, in _get_site_title_and_description
    description = description[:450] + '...' if len(description) > 450 else description
TypeError: object of type 'NoneType' has no len()
 37%|███▋      | 75/201 [02:10<02:58,  1.42s/it]INFO:__main__:Requesting https://github.com/rancher/k3s/blob/master/README.md#what-is-this
INFO:__main__:Getting metadata for https://github.com/rancher/k3s/blob/master/README.md#what-is-this
 38%|███▊      | 76/201 [02:11<02:41,  1.29s/it]INFO:__main__:Requesting https://github.com/rancher/k3s/blob/master/README.md#server-ha
INFO:__main__:Getting metadata for https://github.com/rancher/k3s/blob/master/README.md#server-ha
 38%|███▊      | 77/201 [02:12<02:49,  1.36s/it]INFO:__main__:Requesting https://github.com/rancher/k3s/search?q=ingress&type=Commits
INFO:__main__:Getting metadata for https://github.com/rancher/k3s/search?q=ingress&type=Commits
 39%|███▉      | 78/201 [02:13<02:31,  1.23s/it]INFO:__main__:Requesting https://twitter.com/kelseyhightower/status/935252923721793536
INFO:__main__:Getting metadata for https://twitter.com/kelseyhightower/status/935252923721793536
 39%|███▉      | 79/201 [02:14<02:15,  1.11s/it]INFO:__main__:Requesting https://youtu.be/mMpZpa7uUSk
INFO:__main__:Getting metadata for https://www.youtube.com/watch?v=mMpZpa7uUSk&feature=youtu.be
 40%|███▉      | 80/201 [02:15<02:04,  1.03s/it]INFO:__main__:Requesting https://en.wikipedia.org/wiki/Erlang_(programming_language)
INFO:__main__:Getting metadata for https://en.wikipedia.org/wiki/Erlang_(programming_language)
 40%|████      | 81/201 [02:16<02:16,  1.14s/it]INFO:__main__:Requesting http://erlang.org/pipermail/erlang-questions/2008-October/039261.html
INFO:__main__:Getting metadata for http://erlang.org/pipermail/erlang-questions/2008-October/039261.html
 41%|████      | 82/201 [02:19<03:12,  1.62s/it]INFO:__main__:Requesting https://landscape.cncf.io/category=certified-kubernetes-distribution,certified-kubernetes-hosted,certified-kubernetes-installer&format=card-mode&grouping=category&selected=k3s
INFO:__main__:Getting metadata for https://landscape.cncf.io/category=certified-kubernetes-distribution,certified-kubernetes-hosted,certified-kubernetes-installer&format=card-mode&grouping=category&selected=k3s
ERROR:__main__:Could not get metadata for https://landscape.cncf.io/category=certified-kubernetes-distribution,certified-kubernetes-hosted,certified-kubernetes-installer&format=card-mode&grouping=category&selected=k3s
Traceback (most recent call last):
  File "../_scripts/crawler/crawler.py", line 94, in _get_site_title_and_description
    description = description[:450] + '...' if len(description) > 450 else description
TypeError: object of type 'NoneType' has no len()
 41%|████▏     | 83/201 [02:20<02:27,  1.25s/it]INFO:__main__:Requesting https://www.youtube.com/watch?v=5-5t672vFi4
INFO:__main__:Getting metadata for https://www.youtube.com/watch?v=5-5t672vFi4
 42%|████▏     | 84/201 [02:20<02:10,  1.12s/it]INFO:__main__:Requesting https://medium.com/@cfatechblog/bare-metal-k8s-clustering-at-chick-fil-a-scale-7b0607bd3541
INFO:__main__:Getting metadata for https://medium.com/@cfatechblog/bare-metal-k8s-clustering-at-chick-fil-a-scale-7b0607bd3541
 42%|████▏     | 85/201 [02:21<01:48,  1.07it/s]INFO:__main__:Requesting https://thenewstack.io/rancher-takes-kubernetes-management-to-china/
INFO:__main__:Getting metadata for https://thenewstack.io/rancher-takes-kubernetes-management-to-china/
 43%|████▎     | 86/201 [02:22<01:52,  1.02it/s]INFO:__main__:Requesting https://www.sqlite.org/famous.html
INFO:__main__:Getting metadata for https://www.sqlite.org/famous.html
ERROR:__main__:Could not get metadata for https://www.sqlite.org/famous.html
Traceback (most recent call last):
  File "../_scripts/crawler/crawler.py", line 94, in _get_site_title_and_description
    description = description[:450] + '...' if len(description) > 450 else description
TypeError: object of type 'NoneType' has no len()
 43%|████▎     | 87/201 [02:23<01:39,  1.15it/s]INFO:__main__:Requesting https://godoc.org/github.com/etcd-io/etcd/embed
INFO:__main__:Getting metadata for https://godoc.org/github.com/etcd-io/etcd/embed
 44%|████▍     | 88/201 [02:23<01:13,  1.53it/s]INFO:__main__:Requesting https://github.com/lxc/lxd/blob/master/doc/database.md
INFO:__main__:Getting metadata for https://github.com/lxc/lxd/blob/master/doc/database.md
 44%|████▍     | 89/201 [02:24<01:26,  1.29it/s]INFO:__main__:Requesting https://github.com/CanonicalLtd/dqlite
INFO:__main__:Getting metadata for https://github.com/CanonicalLtd/dqlite
 45%|████▍     | 90/201 [02:25<01:37,  1.14it/s]INFO:__main__:Requesting http://www.pidramble.com
INFO:__main__:Getting metadata for http://www.pidramble.com
 45%|████▌     | 91/201 [02:25<01:17,  1.42it/s]INFO:__main__:Requesting https://blog.hasura.io/draft-vs-gitkube-vs-helm-vs-ksonnet-vs-metaparticle-vs-skaffold-f5aa9561f948/
INFO:__main__:Getting metadata for https://blog.hasura.io/draft-vs-gitkube-vs-helm-vs-ksonnet-vs-metaparticle-vs-skaffold-f5aa9561f948/
 46%|████▌     | 92/201 [02:27<01:42,  1.06it/s]INFO:__main__:Requesting https://kubernetes.io/blog/2018/05/01/developing-on-kubernetes/
INFO:__main__:Getting metadata for https://kubernetes.io/blog/2018/05/01/developing-on-kubernetes/
 46%|████▋     | 93/201 [02:28<02:04,  1.15s/it]INFO:__main__:Requesting https://electronics.stackexchange.com/questions/32200/why-is-spi-flash-memory-so-limited-in-max-size-and-cost-way-more-per-mb-than
INFO:__main__:Getting metadata for https://electronics.stackexchange.com/questions/32200/why-is-spi-flash-memory-so-limited-in-max-size-and-cost-way-more-per-mb-than
 47%|████▋     | 94/201 [02:29<01:38,  1.08it/s]INFO:__main__:Requesting https://github.com/rancher/k3s#flannel
INFO:__main__:Getting metadata for https://github.com/rancher/k3s#flannel
 47%|████▋     | 95/201 [02:30<01:41,  1.05it/s]INFO:__main__:Requesting https://bugs.chromium.org/p/chromium/issues/detail?id=878034
INFO:__main__:Getting metadata for https://bugs.chromium.org/p/chromium/issues/detail?id=878034
ERROR:__main__:Could not get metadata for https://bugs.chromium.org/p/chromium/issues/detail?id=878034
Traceback (most recent call last):
  File "../_scripts/crawler/crawler.py", line 94, in _get_site_title_and_description
    description = description[:450] + '...' if len(description) > 450 else description
TypeError: object of type 'NoneType' has no len()
 48%|████▊     | 96/201 [02:32<02:13,  1.27s/it]INFO:__main__:Requesting https://medium.com/@kvaps/run-kubernetes-in-lxc-container-f04aa94b6c9c
INFO:__main__:Getting metadata for https://medium.com/@kvaps/run-kubernetes-in-lxc-container-f04aa94b6c9c
 48%|████▊     | 97/201 [02:32<01:49,  1.05s/it]INFO:__main__:Requesting https://www.eetimes.com/document.asp?doc_id=1334373
ERROR:__main__:Could not reach https://www.eetimes.com/document.asp?doc_id=1334373
Traceback (most recent call last):
  File "/home/travis/virtualenv/python3.6.3/lib/python3.6/site-packages/urllib3/connectionpool.py", line 384, in _make_request
    six.raise_from(e, None)
  File "<string>", line 2, in raise_from
  File "/home/travis/virtualenv/python3.6.3/lib/python3.6/site-packages/urllib3/connectionpool.py", line 380, in _make_request
    httplib_response = conn.getresponse()
  File "/opt/python/3.6.3/lib/python3.6/http/client.py", line 1331, in getresponse
    response.begin()
  File "/opt/python/3.6.3/lib/python3.6/http/client.py", line 297, in begin
    version, status, reason = self._read_status()
  File "/opt/python/3.6.3/lib/python3.6/http/client.py", line 258, in _read_status
    line = str(self.fp.readline(_MAXLINE + 1), "iso-8859-1")
  File "/opt/python/3.6.3/lib/python3.6/socket.py", line 586, in readinto
    return self._sock.recv_into(b)
  File "/opt/python/3.6.3/lib/python3.6/ssl.py", line 1009, in recv_into
    return self.read(nbytes, buffer)
  File "/opt/python/3.6.3/lib/python3.6/ssl.py", line 871, in read
    return self._sslobj.read(len, buffer)
  File "/opt/python/3.6.3/lib/python3.6/ssl.py", line 631, in read
    v = self._sslobj.read(len, buffer)
socket.timeout: The read operation timed out

During handling of the above exception, another exception occurred:

Traceback (most recent call last):
  File "/home/travis/virtualenv/python3.6.3/lib/python3.6/site-packages/requests/adapters.py", line 449, in send
    timeout=timeout
  File "/home/travis/virtualenv/python3.6.3/lib/python3.6/site-packages/urllib3/connectionpool.py", line 638, in urlopen
    _stacktrace=sys.exc_info()[2])
  File "/home/travis/virtualenv/python3.6.3/lib/python3.6/site-packages/urllib3/util/retry.py", line 367, in increment
    raise six.reraise(type(error), error, _stacktrace)
  File "/home/travis/virtualenv/python3.6.3/lib/python3.6/site-packages/urllib3/packages/six.py", line 686, in reraise
    raise value
  File "/home/travis/virtualenv/python3.6.3/lib/python3.6/site-packages/urllib3/connectionpool.py", line 600, in urlopen
    chunked=chunked)
  File "/home/travis/virtualenv/python3.6.3/lib/python3.6/site-packages/urllib3/connectionpool.py", line 386, in _make_request
    self._raise_timeout(err=e, url=url, timeout_value=read_timeout)
  File "/home/travis/virtualenv/python3.6.3/lib/python3.6/site-packages/urllib3/connectionpool.py", line 306, in _raise_timeout
    raise ReadTimeoutError(self, url, "Read timed out. (read timeout=%s)" % timeout_value)
urllib3.exceptions.ReadTimeoutError: HTTPSConnectionPool(host='www.eetimes.com', port=443): Read timed out. (read timeout=6)

During handling of the above exception, another exception occurred:

Traceback (most recent call last):
  File "../_scripts/crawler/crawler.py", line 210, in metafy_url
    response = requests.get(url, timeout=6, headers={'User-Agent': 'Mozilla/5.0'})
  File "/home/travis/virtualenv/python3.6.3/lib/python3.6/site-packages/requests/api.py", line 75, in get
    return request('get', url, params=params, **kwargs)
  File "/home/travis/virtualenv/python3.6.3/lib/python3.6/site-packages/requests/api.py", line 60, in request
    return session.request(method=method, url=url, **kwargs)
  File "/home/travis/virtualenv/python3.6.3/lib/python3.6/site-packages/requests/sessions.py", line 533, in request
    resp = self.send(prep, **send_kwargs)
  File "/home/travis/virtualenv/python3.6.3/lib/python3.6/site-packages/requests/sessions.py", line 646, in send
    r = adapter.send(request, **kwargs)
  File "/home/travis/virtualenv/python3.6.3/lib/python3.6/site-packages/requests/adapters.py", line 529, in send
    raise ReadTimeout(e, request=request)
requests.exceptions.ReadTimeout: HTTPSConnectionPool(host='www.eetimes.com', port=443): Read timed out. (read timeout=6)
 49%|████▉     | 98/201 [02:38<04:26,  2.59s/it]INFO:__main__:Requesting https://training.ti.com/tis-bulk-acoustic-wave-clocking-technology-0
INFO:__main__:Getting metadata for https://training.ti.com/tis-bulk-acoustic-wave-clocking-technology-0
ERROR:__main__:Could not get metadata for https://training.ti.com/tis-bulk-acoustic-wave-clocking-technology-0
Traceback (most recent call last):
  File "../_scripts/crawler/crawler.py", line 94, in _get_site_title_and_description
    description = description[:450] + '...' if len(description) > 450 else description
TypeError: object of type 'NoneType' has no len()
 49%|████▉     | 99/201 [02:41<04:34,  2.69s/it]INFO:__main__:Requesting https://www.confluent.io/blog/noise-mapping-ksql-raspberry-pi-software-defined-radio
INFO:__main__:Getting metadata for https://www.confluent.io/blog/noise-mapping-ksql-raspberry-pi-software-defined-radio
 50%|████▉     | 100/201 [02:42<03:13,  1.92s/it]INFO:__main__:Requesting https://webtrak.emsbk.com/lax4
INFO:__main__:Getting metadata for https://webtrak.emsbk.com/lax4
 50%|█████     | 101/201 [02:43<02:58,  1.78s/it]INFO:__main__:Requesting https://www.nature.com/articles/d41586-019-00577-0
INFO:__main__:Getting metadata for https://www.nature.com/articles/d41586-019-00577-0
 51%|█████     | 102/201 [02:45<03:16,  1.98s/it]INFO:__main__:Requesting https://physicsfm-frontiers.blogspot.com
INFO:__main__:Getting metadata for https://physicsfm-frontiers.blogspot.com
ERROR:__main__:Could not get metadata for https://physicsfm-frontiers.blogspot.com
Traceback (most recent call last):
  File "../_scripts/crawler/crawler.py", line 94, in _get_site_title_and_description
    description = description[:450] + '...' if len(description) > 450 else description
TypeError: object of type 'NoneType' has no len()
 51%|█████     | 103/201 [02:46<02:24,  1.47s/it]INFO:__main__:Requesting https://en.wikipedia.org/wiki/Semi-empirical_mass_formula
INFO:__main__:Getting metadata for https://en.wikipedia.org/wiki/Semi-empirical_mass_formula
 52%|█████▏    | 104/201 [02:48<02:34,  1.60s/it]INFO:__main__:Requesting https://pubs.rsc.org/en/content/articlehtml/2013/cp/c3cp51500a
INFO:__main__:Getting metadata for https://pubs.rsc.org/en/content/articlehtml/2013/cp/c3cp51500a
ERROR:__main__:Could not get metadata for https://pubs.rsc.org/en/content/articlehtml/2013/cp/c3cp51500a
Traceback (most recent call last):
  File "/home/travis/virtualenv/python3.6.3/lib/python3.6/site-packages/urllib3/connectionpool.py", line 600, in urlopen
    chunked=chunked)
  File "/home/travis/virtualenv/python3.6.3/lib/python3.6/site-packages/urllib3/connectionpool.py", line 384, in _make_request
    six.raise_from(e, None)
  File "<string>", line 2, in raise_from
  File "/home/travis/virtualenv/python3.6.3/lib/python3.6/site-packages/urllib3/connectionpool.py", line 380, in _make_request
    httplib_response = conn.getresponse()
  File "/opt/python/3.6.3/lib/python3.6/http/client.py", line 1331, in getresponse
    response.begin()
  File "/opt/python/3.6.3/lib/python3.6/http/client.py", line 297, in begin
    version, status, reason = self._read_status()
  File "/opt/python/3.6.3/lib/python3.6/http/client.py", line 266, in _read_status
    raise RemoteDisconnected("Remote end closed connection without"
http.client.RemoteDisconnected: Remote end closed connection without response

During handling of the above exception, another exception occurred:

Traceback (most recent call last):
  File "/home/travis/virtualenv/python3.6.3/lib/python3.6/site-packages/requests/adapters.py", line 449, in send
    timeout=timeout
  File "/home/travis/virtualenv/python3.6.3/lib/python3.6/site-packages/urllib3/connectionpool.py", line 638, in urlopen
    _stacktrace=sys.exc_info()[2])
  File "/home/travis/virtualenv/python3.6.3/lib/python3.6/site-packages/urllib3/util/retry.py", line 367, in increment
    raise six.reraise(type(error), error, _stacktrace)
  File "/home/travis/virtualenv/python3.6.3/lib/python3.6/site-packages/urllib3/packages/six.py", line 685, in reraise
    raise value.with_traceback(tb)
  File "/home/travis/virtualenv/python3.6.3/lib/python3.6/site-packages/urllib3/connectionpool.py", line 600, in urlopen
    chunked=chunked)
  File "/home/travis/virtualenv/python3.6.3/lib/python3.6/site-packages/urllib3/connectionpool.py", line 384, in _make_request
    six.raise_from(e, None)
  File "<string>", line 2, in raise_from
  File "/home/travis/virtualenv/python3.6.3/lib/python3.6/site-packages/urllib3/connectionpool.py", line 380, in _make_request
    httplib_response = conn.getresponse()
  File "/opt/python/3.6.3/lib/python3.6/http/client.py", line 1331, in getresponse
    response.begin()
  File "/opt/python/3.6.3/lib/python3.6/http/client.py", line 297, in begin
    version, status, reason = self._read_status()
  File "/opt/python/3.6.3/lib/python3.6/http/client.py", line 266, in _read_status
    raise RemoteDisconnected("Remote end closed connection without"
urllib3.exceptions.ProtocolError: ('Connection aborted.', RemoteDisconnected('Remote end closed connection without response',))

During handling of the above exception, another exception occurred:

Traceback (most recent call last):
  File "/home/travis/virtualenv/python3.6.3/lib/python3.6/site-packages/webpreview/previews.py", line 34, in __init__
    res = requests.get(url, timeout=timeout, headers=headers)
  File "/home/travis/virtualenv/python3.6.3/lib/python3.6/site-packages/requests/api.py", line 75, in get
    return request('get', url, params=params, **kwargs)
  File "/home/travis/virtualenv/python3.6.3/lib/python3.6/site-packages/requests/api.py", line 60, in request
    return session.request(method=method, url=url, **kwargs)
  File "/home/travis/virtualenv/python3.6.3/lib/python3.6/site-packages/requests/sessions.py", line 533, in request
    resp = self.send(prep, **send_kwargs)
  File "/home/travis/virtualenv/python3.6.3/lib/python3.6/site-packages/requests/sessions.py", line 646, in send
    r = adapter.send(request, **kwargs)
  File "/home/travis/virtualenv/python3.6.3/lib/python3.6/site-packages/requests/adapters.py", line 498, in send
    raise ConnectionError(err, request=request)
requests.exceptions.ConnectionError: ('Connection aborted.', RemoteDisconnected('Remote end closed connection without response',))

During handling of the above exception, another exception occurred:

Traceback (most recent call last):
  File "../_scripts/crawler/crawler.py", line 93, in _get_site_title_and_description
    title, description, _ = web_preview(url, content=content)
  File "/home/travis/virtualenv/python3.6.3/lib/python3.6/site-packages/webpreview/previews.py", line 190, in web_preview
    og = OpenGraph(url, ['og:title', 'og:description', 'og:image'], timeout=timeout, headers=headers, content=content)
  File "/home/travis/virtualenv/python3.6.3/lib/python3.6/site-packages/webpreview/previews.py", line 165, in __init__
    super(OpenGraph, self).__init__(*args, **kwargs)
  File "/home/travis/virtualenv/python3.6.3/lib/python3.6/site-packages/webpreview/previews.py", line 131, in __init__
    super(SocialPreviewBase, self).__init__(*args, **kwargs)
  File "/home/travis/virtualenv/python3.6.3/lib/python3.6/site-packages/webpreview/previews.py", line 36, in __init__
    raise URLUnreachable("The URL does not exist.")
webpreview.excepts.URLUnreachable: The URL does not exist.
 52%|█████▏    | 105/201 [02:50<02:50,  1.78s/it]INFO:__main__:Requesting https://decryptmedia.com/5414/alleged-coinomi-exploit-concern
INFO:__main__:Getting metadata for https://decryptmedia.com/5414/alleged-coinomi-exploit-concern
 53%|█████▎    | 106/201 [02:50<02:04,  1.31s/it]INFO:__main__:Requesting https://medium.com/coinomi/official-statement-on-spell-check-findings-547ca348676b
INFO:__main__:Getting metadata for https://medium.com/coinomi/official-statement-on-spell-check-findings-547ca348676b
 53%|█████▎    | 107/201 [02:50<01:39,  1.06s/it]INFO:__main__:Requesting https://developer.android.com/reference/android/widget/EditText
INFO:__main__:Getting metadata for https://developer.android.com/reference/android/widget/EditText
ERROR:__main__:Could not get metadata for https://developer.android.com/reference/android/widget/EditText
Traceback (most recent call last):
  File "../_scripts/crawler/crawler.py", line 94, in _get_site_title_and_description
    description = description[:450] + '...' if len(description) > 450 else description
TypeError: object of type 'NoneType' has no len()
 54%|█████▎    | 108/201 [02:55<03:18,  2.13s/it]INFO:__main__:Requesting https://www.avoid-coinomi.com/
INFO:__main__:Getting metadata for https://www.avoid-coinomi.com
ERROR:__main__:Could not get metadata for https://www.avoid-coinomi.com
Traceback (most recent call last):
  File "../_scripts/crawler/crawler.py", line 94, in _get_site_title_and_description
    description = description[:450] + '...' if len(description) > 450 else description
TypeError: object of type 'NoneType' has no len()
 54%|█████▍    | 109/201 [02:58<03:24,  2.22s/it]INFO:__main__:Requesting https://www.bankofamerica.com/privacy/faq/data-compromise-faq.go
INFO:__main__:Getting metadata for https://www.bankofamerica.com/privacy/faq/data-compromise-faq.go
 55%|█████▍    | 110/201 [02:59<03:09,  2.08s/it]INFO:__main__:Requesting https://e.vnexpress.net/news/news/vietnam-bank-ceo-gets-life-property-mogul-17-years-in-jail-3857282.html
INFO:__main__:Getting metadata for https://e.vnexpress.net/news/news/vietnam-bank-ceo-gets-life-property-mogul-17-years-in-jail-3857282.html
 55%|█████▌    | 111/201 [03:02<03:31,  2.35s/it]INFO:__main__:Requesting https://www.ledger.com/
INFO:__main__:Getting metadata for https://www.ledger.com
 56%|█████▌    | 112/201 [03:03<02:38,  1.78s/it]INFO:__main__:Requesting https://www.npr.org/sections/health-shots/2019/02/26/696321475/cancer-complications-confusing-bills-maddening-errors-and-endless-phone-calls
INFO:__main__:Getting metadata for https://www.npr.org/sections/health-shots/2019/02/26/696321475/cancer-complications-confusing-bills-maddening-errors-and-endless-phone-calls
 56%|█████▌    | 113/201 [03:03<01:55,  1.31s/it]INFO:__main__:Requesting https://www.propublica.org/article/why-your-health-insurer-does-not-care-about-your-big-bills
INFO:__main__:Getting metadata for https://www.propublica.org/article/why-your-health-insurer-does-not-care-about-your-big-bills
 57%|█████▋    | 114/201 [03:03<01:28,  1.02s/it]INFO:__main__:Requesting https://www.wcrf.org/dietandcancer/cancer-trends/data-cancer-frequency-country
INFO:__main__:Getting metadata for https://www.wcrf.org/dietandcancer/cancer-trends/data-cancer-frequency-country
 57%|█████▋    | 115/201 [03:04<01:30,  1.05s/it]INFO:__main__:Requesting https://www.wcrf.org/dietandcancer/cancer-trends/data-cancer..
 58%|█████▊    | 116/201 [03:05<01:25,  1.01s/it]INFO:__main__:Requesting https://www.ncbi.nlm.nih.gov/pubmed/18639491
INFO:__main__:Getting metadata for https://www.ncbi.nlm.nih.gov/pubmed/18639491
 58%|█████▊    | 117/201 [03:08<02:08,  1.54s/it]INFO:__main__:Requesting https://news.ycombinator.com/newsguidelines.html
ERROR:__main__:Could not reach https://news.ycombinator.com/newsguidelines.html
Traceback (most recent call last):
  File "/home/travis/virtualenv/python3.6.3/lib/python3.6/site-packages/urllib3/connection.py", line 159, in _new_conn
    (self._dns_host, self.port), self.timeout, **extra_kw)
  File "/home/travis/virtualenv/python3.6.3/lib/python3.6/site-packages/urllib3/util/connection.py", line 80, in create_connection
    raise err
  File "/home/travis/virtualenv/python3.6.3/lib/python3.6/site-packages/urllib3/util/connection.py", line 70, in create_connection
    sock.connect(sa)
socket.timeout: timed out

During handling of the above exception, another exception occurred:

Traceback (most recent call last):
  File "/home/travis/virtualenv/python3.6.3/lib/python3.6/site-packages/urllib3/connectionpool.py", line 600, in urlopen
    chunked=chunked)
  File "/home/travis/virtualenv/python3.6.3/lib/python3.6/site-packages/urllib3/connectionpool.py", line 343, in _make_request
    self._validate_conn(conn)
  File "/home/travis/virtualenv/python3.6.3/lib/python3.6/site-packages/urllib3/connectionpool.py", line 839, in _validate_conn
    conn.connect()
  File "/home/travis/virtualenv/python3.6.3/lib/python3.6/site-packages/urllib3/connection.py", line 301, in connect
    conn = self._new_conn()
  File "/home/travis/virtualenv/python3.6.3/lib/python3.6/site-packages/urllib3/connection.py", line 164, in _new_conn
    (self.host, self.timeout))
urllib3.exceptions.ConnectTimeoutError: (<urllib3.connection.VerifiedHTTPSConnection object at 0x7f7ac021c3c8>, 'Connection to news.ycombinator.com timed out. (connect timeout=6)')

During handling of the above exception, another exception occurred:

Traceback (most recent call last):
  File "/home/travis/virtualenv/python3.6.3/lib/python3.6/site-packages/requests/adapters.py", line 449, in send
    timeout=timeout
  File "/home/travis/virtualenv/python3.6.3/lib/python3.6/site-packages/urllib3/connectionpool.py", line 638, in urlopen
    _stacktrace=sys.exc_info()[2])
  File "/home/travis/virtualenv/python3.6.3/lib/python3.6/site-packages/urllib3/util/retry.py", line 398, in increment
    raise MaxRetryError(_pool, url, error or ResponseError(cause))
urllib3.exceptions.MaxRetryError: HTTPSConnectionPool(host='news.ycombinator.com', port=443): Max retries exceeded with url: /newsguidelines.html (Caused by ConnectTimeoutError(<urllib3.connection.VerifiedHTTPSConnection object at 0x7f7ac021c3c8>, 'Connection to news.ycombinator.com timed out. (connect timeout=6)'))

During handling of the above exception, another exception occurred:

Traceback (most recent call last):
  File "../_scripts/crawler/crawler.py", line 210, in metafy_url
    response = requests.get(url, timeout=6, headers={'User-Agent': 'Mozilla/5.0'})
  File "/home/travis/virtualenv/python3.6.3/lib/python3.6/site-packages/requests/api.py", line 75, in get
    return request('get', url, params=params, **kwargs)
  File "/home/travis/virtualenv/python3.6.3/lib/python3.6/site-packages/requests/api.py", line 60, in request
    return session.request(method=method, url=url, **kwargs)
  File "/home/travis/virtualenv/python3.6.3/lib/python3.6/site-packages/requests/sessions.py", line 533, in request
    resp = self.send(prep, **send_kwargs)
  File "/home/travis/virtualenv/python3.6.3/lib/python3.6/site-packages/requests/sessions.py", line 646, in send
    r = adapter.send(request, **kwargs)
  File "/home/travis/virtualenv/python3.6.3/lib/python3.6/site-packages/requests/adapters.py", line 504, in send
    raise ConnectTimeout(e, request=request)
requests.exceptions.ConnectTimeout: HTTPSConnectionPool(host='news.ycombinator.com', port=443): Max retries exceeded with url: /newsguidelines.html (Caused by ConnectTimeoutError(<urllib3.connection.VerifiedHTTPSConnection object at 0x7f7ac021c3c8>, 'Connection to news.ycombinator.com timed out. (connect timeout=6)'))
 59%|█████▊    | 118/201 [03:14<03:59,  2.89s/it]INFO:__main__:Requesting https://en.wikipedia.org/wiki/Thalidomide
INFO:__main__:Getting metadata for https://en.wikipedia.org/wiki/Thalidomide
 59%|█████▉    | 119/201 [03:17<03:45,  2.75s/it]INFO:__main__:Requesting https://en.wikipedia.org/wiki/Frances_Oldham_Kelsey
INFO:__main__:Getting metadata for https://en.wikipedia.org/wiki/Frances_Oldham_Kelsey
 60%|█████▉    | 120/201 [03:18<03:07,  2.32s/it]INFO:__main__:Requesting https://en.m.wikipedia.org/wiki/Prescription_costs
INFO:__main__:Getting metadata for https://en.m.wikipedia.org/wiki/Prescription_costs
 60%|██████    | 121/201 [03:19<02:34,  1.94s/it]INFO:__main__:Requesting https://www.cancer.gov/about-cancer/understanding/statistics
INFO:__main__:Getting metadata for https://www.cancer.gov/about-cancer/understanding/statistics
 61%|██████    | 122/201 [03:20<02:02,  1.55s/it]INFO:__main__:Requesting https://jamanetwork.com/journals/jama/article-abstract/2674671
INFO:__main__:Getting metadata for https://jamanetwork.com/journals/jama/article-abstract/2674671
ERROR:__main__:Could not get metadata for https://jamanetwork.com/journals/jama/article-abstract/2674671
Traceback (most recent call last):
  File "/home/travis/virtualenv/python3.6.3/lib/python3.6/site-packages/urllib3/connectionpool.py", line 600, in urlopen
    chunked=chunked)
  File "/home/travis/virtualenv/python3.6.3/lib/python3.6/site-packages/urllib3/connectionpool.py", line 384, in _make_request
    six.raise_from(e, None)
  File "<string>", line 2, in raise_from
  File "/home/travis/virtualenv/python3.6.3/lib/python3.6/site-packages/urllib3/connectionpool.py", line 380, in _make_request
    httplib_response = conn.getresponse()
  File "/opt/python/3.6.3/lib/python3.6/http/client.py", line 1331, in getresponse
    response.begin()
  File "/opt/python/3.6.3/lib/python3.6/http/client.py", line 297, in begin
    version, status, reason = self._read_status()
  File "/opt/python/3.6.3/lib/python3.6/http/client.py", line 258, in _read_status
    line = str(self.fp.readline(_MAXLINE + 1), "iso-8859-1")
  File "/opt/python/3.6.3/lib/python3.6/socket.py", line 586, in readinto
    return self._sock.recv_into(b)
  File "/opt/python/3.6.3/lib/python3.6/ssl.py", line 1009, in recv_into
    return self.read(nbytes, buffer)
  File "/opt/python/3.6.3/lib/python3.6/ssl.py", line 871, in read
    return self._sslobj.read(len, buffer)
  File "/opt/python/3.6.3/lib/python3.6/ssl.py", line 631, in read
    v = self._sslobj.read(len, buffer)
ConnectionResetError: [Errno 104] Connection reset by peer

During handling of the above exception, another exception occurred:

Traceback (most recent call last):
  File "/home/travis/virtualenv/python3.6.3/lib/python3.6/site-packages/requests/adapters.py", line 449, in send
    timeout=timeout
  File "/home/travis/virtualenv/python3.6.3/lib/python3.6/site-packages/urllib3/connectionpool.py", line 638, in urlopen
    _stacktrace=sys.exc_info()[2])
  File "/home/travis/virtualenv/python3.6.3/lib/python3.6/site-packages/urllib3/util/retry.py", line 367, in increment
    raise six.reraise(type(error), error, _stacktrace)
  File "/home/travis/virtualenv/python3.6.3/lib/python3.6/site-packages/urllib3/packages/six.py", line 685, in reraise
    raise value.with_traceback(tb)
  File "/home/travis/virtualenv/python3.6.3/lib/python3.6/site-packages/urllib3/connectionpool.py", line 600, in urlopen
    chunked=chunked)
  File "/home/travis/virtualenv/python3.6.3/lib/python3.6/site-packages/urllib3/connectionpool.py", line 384, in _make_request
    six.raise_from(e, None)
  File "<string>", line 2, in raise_from
  File "/home/travis/virtualenv/python3.6.3/lib/python3.6/site-packages/urllib3/connectionpool.py", line 380, in _make_request
    httplib_response = conn.getresponse()
  File "/opt/python/3.6.3/lib/python3.6/http/client.py", line 1331, in getresponse
    response.begin()
  File "/opt/python/3.6.3/lib/python3.6/http/client.py", line 297, in begin
    version, status, reason = self._read_status()
  File "/opt/python/3.6.3/lib/python3.6/http/client.py", line 258, in _read_status
    line = str(self.fp.readline(_MAXLINE + 1), "iso-8859-1")
  File "/opt/python/3.6.3/lib/python3.6/socket.py", line 586, in readinto
    return self._sock.recv_into(b)
  File "/opt/python/3.6.3/lib/python3.6/ssl.py", line 1009, in recv_into
    return self.read(nbytes, buffer)
  File "/opt/python/3.6.3/lib/python3.6/ssl.py", line 871, in read
    return self._sslobj.read(len, buffer)
  File "/opt/python/3.6.3/lib/python3.6/ssl.py", line 631, in read
    v = self._sslobj.read(len, buffer)
urllib3.exceptions.ProtocolError: ('Connection aborted.', ConnectionResetError(104, 'Connection reset by peer'))

During handling of the above exception, another exception occurred:

Traceback (most recent call last):
  File "/home/travis/virtualenv/python3.6.3/lib/python3.6/site-packages/webpreview/previews.py", line 34, in __init__
    res = requests.get(url, timeout=timeout, headers=headers)
  File "/home/travis/virtualenv/python3.6.3/lib/python3.6/site-packages/requests/api.py", line 75, in get
    return request('get', url, params=params, **kwargs)
  File "/home/travis/virtualenv/python3.6.3/lib/python3.6/site-packages/requests/api.py", line 60, in request
    return session.request(method=method, url=url, **kwargs)
  File "/home/travis/virtualenv/python3.6.3/lib/python3.6/site-packages/requests/sessions.py", line 533, in request
    resp = self.send(prep, **send_kwargs)
  File "/home/travis/virtualenv/python3.6.3/lib/python3.6/site-packages/requests/sessions.py", line 646, in send
    r = adapter.send(request, **kwargs)
  File "/home/travis/virtualenv/python3.6.3/lib/python3.6/site-packages/requests/adapters.py", line 498, in send
    raise ConnectionError(err, request=request)
requests.exceptions.ConnectionError: ('Connection aborted.', ConnectionResetError(104, 'Connection reset by peer'))

During handling of the above exception, another exception occurred:

Traceback (most recent call last):
  File "../_scripts/crawler/crawler.py", line 93, in _get_site_title_and_description
    title, description, _ = web_preview(url, content=content)
  File "/home/travis/virtualenv/python3.6.3/lib/python3.6/site-packages/webpreview/previews.py", line 190, in web_preview
    og = OpenGraph(url, ['og:title', 'og:description', 'og:image'], timeout=timeout, headers=headers, content=content)
  File "/home/travis/virtualenv/python3.6.3/lib/python3.6/site-packages/webpreview/previews.py", line 165, in __init__
    super(OpenGraph, self).__init__(*args, **kwargs)
  File "/home/travis/virtualenv/python3.6.3/lib/python3.6/site-packages/webpreview/previews.py", line 131, in __init__
    super(SocialPreviewBase, self).__init__(*args, **kwargs)
  File "/home/travis/virtualenv/python3.6.3/lib/python3.6/site-packages/webpreview/previews.py", line 36, in __init__
    raise URLUnreachable("The URL does not exist.")
webpreview.excepts.URLUnreachable: The URL does not exist.
 61%|██████    | 123/201 [03:21<01:55,  1.48s/it]INFO:__main__:Requesting https://www.amazon.com/Getting-Health-Reform-Right-Performance/dp/019537150X
INFO:__main__:Getting metadata for https://www.amazon.com/Getting-Health-Reform-Right-Performance/dp/019537150X
 62%|██████▏   | 124/201 [03:24<02:35,  2.02s/it]INFO:__main__:Requesting https://www.forbes.com/sites/maggiemcgrath/2016/01/06/63-of-americans-dont-have-enough-savings-to-cover-a-500-emergency/#14c251a34e0d
INFO:__main__:Getting metadata for https://www.forbes.com/sites/maggiemcgrath/2016/01/06/63-of-americans-dont-have-enough-savings-to-cover-a-500-emergency/#14c251a34e0d
 62%|██████▏   | 125/201 [03:25<02:14,  1.77s/it]INFO:__main__:Requesting https://slate.com/technology/2016/04/biomedicine-facing-a-worse-replication-crisis-than-the-one-plaguing-psychology.html
INFO:__main__:Getting metadata for https://slate.com/technology/2016/04/biomedicine-facing-a-worse-replication-crisis-than-the-one-plaguing-psychology.html
 63%|██████▎   | 126/201 [03:26<01:46,  1.42s/it]INFO:__main__:Requesting https://www.bmj.com/content/357/bmj.j2097
INFO:__main__:Getting metadata for https://www.bmj.com/content/357/bmj.j2097
 63%|██████▎   | 127/201 [03:28<02:00,  1.63s/it]INFO:__main__:Requesting https://www.cbsnews.com/news/most-americans-cant-afford-a-500-emergency-expense/
INFO:__main__:Getting metadata for https://www.cbsnews.com/news/most-americans-cant-afford-a-500-emergency-expense/
 64%|██████▎   | 128/201 [03:29<01:33,  1.29s/it]INFO:__main__:Requesting http://www.ascopost.com/issues/may-25-2016/the-arrival-of-generic-imatinib-into-the-us-market-an-educational-event/
INFO:__main__:Getting metadata for http://www.ascopost.com/issues/may-25-2016/the-arrival-of-generic-imatinib-into-the-us-market-an-educational-event/
 64%|██████▍   | 129/201 [03:30<01:39,  1.38s/it]INFO:__main__:Requesting https://www.cbsnews.com/news/giuliani-ad-chances/
INFO:__main__:Getting metadata for https://www.cbsnews.com/news/giuliani-ad-chances/
 65%|██████▍   | 130/201 [03:31<01:16,  1.08s/it]INFO:__main__:Requesting https://www.nytimes.com/2019/02/20/opinion/health-care-germany.html
INFO:__main__:Getting metadata for https://www.nytimes.com/2019/02/20/opinion/health-care-germany.html
 65%|██████▌   | 131/201 [03:31<00:58,  1.20it/s]INFO:__main__:Requesting https://www.pbs.org/wgbh/pages/frontline/sickaroundtheworld/
INFO:__main__:Getting metadata for https://www.pbs.org/wgbh/pages/frontline/sickaroundtheworld/
 66%|██████▌   | 132/201 [03:32<00:57,  1.19it/s]INFO:__main__:Requesting https://www.nytimes.com/2019/02/23/us/politics/medicare-for-all-lobbyists.html
INFO:__main__:Getting metadata for https://www.nytimes.com/2019/02/23/us/politics/medicare-for-all-lobbyists.html
 66%|██████▌   | 133/201 [03:32<00:44,  1.53it/s]INFO:__main__:Requesting https://thenib.com/americans-are-drowning-in-debt
INFO:__main__:Getting metadata for https://thenib.com/americans-are-drowning-in-debt
 67%|██████▋   | 134/201 [03:32<00:40,  1.67it/s]INFO:__main__:Requesting https://www.wnycstudios.org/story/worth
INFO:__main__:Getting metadata for https://www.wnycstudios.org/story/worth
 67%|██████▋   | 135/201 [03:33<00:38,  1.74it/s]INFO:__main__:Requesting https://www.researchgate.net/figure/Paid-sick-days-and-sick-leave-in-22-countries-worker-at-median-earnings-full-time_fig1_41720650
 68%|██████▊   | 136/201 [03:33<00:32,  2.03it/s]INFO:__main__:Requesting https://www.forbes.com/sites/quora/2017/06/13/why-the-us-has-better-cancer-survival-rates-than-the-rest-of-the-world/#37e92baa4b67
INFO:__main__:Getting metadata for https://www.forbes.com/sites/quora/2017/06/13/why-the-us-has-better-cancer-survival-rates-than-the-rest-of-the-world/#37e92baa4b67
 68%|██████▊   | 137/201 [03:34<00:34,  1.88it/s]INFO:__main__:Requesting https://www.cbc.ca/news/canada/british-columbia/a-tale-of-2-friends-with-breast-cancer-1-has-coverage-for-costly-drug-the-other-forced-to-pay-1.4495123
INFO:__main__:Getting metadata for https://www.cbc.ca/news/canada/british-columbia/a-tale-of-2-friends-with-breast-cancer-1-has-coverage-for-costly-drug-the-other-forced-to-pay-1.4495123
 69%|██████▊   | 138/201 [03:34<00:29,  2.13it/s]INFO:__main__:Requesting https://en.m.wikipedia.org/wiki/Chaoulli_v_Quebec_(AG)
INFO:__main__:Getting metadata for https://en.m.wikipedia.org/wiki/Chaoulli_v_Quebec_(AG)
 69%|██████▉   | 139/201 [03:35<00:36,  1.69it/s]INFO:__main__:Requesting https://www.scientificamerican.com/article/how-the-u-s-pays-3-times-more-for-drugs/
INFO:__main__:Getting metadata for https://www.scientificamerican.com/article/how-the-u-s-pays-3-times-more-for-drugs/
 70%|██████▉   | 140/201 [03:36<00:42,  1.45it/s]INFO:__main__:Requesting https://text.npr.org/s.php?sId=696321475
INFO:__main__:Getting metadata for https://text.npr.org/s.php?sId=696321475
ERROR:__main__:Could not get metadata for https://text.npr.org/s.php?sId=696321475
Traceback (most recent call last):
  File "../_scripts/crawler/crawler.py", line 94, in _get_site_title_and_description
    description = description[:450] + '...' if len(description) > 450 else description
TypeError: object of type 'NoneType' has no len()
 70%|███████   | 141/201 [03:37<00:42,  1.40it/s]INFO:__main__:Requesting https://www.policymed.com/2014/12/a-tough-road-cost-to-develop-one-new-drug-is-26-billion-approval-rate-for-drugs-entering-clinical-de.html
INFO:__main__:Getting metadata for https://www.policymed.com/2014/12/a-tough-road-cost-to-develop-one-new-drug-is-26-billion-approval-rate-for-drugs-entering-clinical-de.html
 71%|███████   | 142/201 [03:37<00:37,  1.58it/s]INFO:__main__:Requesting https://www.aafp.org/news/education-professional-development/20171004matchanalysis.html
INFO:__main__:Getting metadata for https://www.aafp.org/news/education-professional-development/20171004matchanalysis.html
 71%|███████   | 143/201 [03:38<00:35,  1.62it/s]INFO:__main__:Requesting https://www.washingtonexaminer.com/thanks-to-doctors-there-arent-enough-doctors
INFO:__main__:Getting metadata for https://www.washingtonexaminer.com/thanks-to-doctors-there-arent-enough-doctors
 72%|███████▏  | 144/201 [03:38<00:36,  1.55it/s]INFO:__main__:Requesting https://www.kaptest.com/study/mcat/how-long-does-it-take-to-become-a-doctor/
INFO:__main__:Getting metadata for https://www.kaptest.com/study/mcat/how-long-does-it-take-to-become-a-doctor/
 72%|███████▏  | 145/201 [03:40<00:51,  1.10it/s]INFO:__main__:Requesting https://www.usnews.com/education/blogs/medical-school-admissions-doctor/2015/04/21/weigh-medical-school-carefully-as-an-older-applicant
 73%|███████▎  | 146/201 [03:40<00:37,  1.49it/s]INFO:__main__:Requesting https://www.aamc.org/advocacy/gme/71178/gme_gme0012.html
INFO:__main__:Getting metadata for https://www.aamc.org/advocacy/gme/71178/gme_gme0012.html
 73%|███████▎  | 147/201 [03:41<00:42,  1.27it/s]INFO:__main__:Requesting https://jobs.lever.co/buildzoom
INFO:__main__:Getting metadata for https://jobs.lever.co/buildzoom
 74%|███████▎  | 148/201 [03:42<00:41,  1.28it/s]INFO:__main__:Requesting https://github.com/cablespaghetti/kubeadm-aws
INFO:__main__:Getting metadata for https://github.com/cablespaghetti/kubeadm-aws
 74%|███████▍  | 149/201 [03:43<00:45,  1.14it/s]INFO:__main__:Requesting https://github.com/hobby-kube/guide
INFO:__main__:Getting metadata for https://github.com/hobby-kube/guide
 75%|███████▍  | 150/201 [03:44<00:43,  1.16it/s]INFO:__main__:Requesting https://www.ovh.co.uk/kubernetes/
INFO:__main__:Getting metadata for https://www.ovh.co.uk/kubernetes/
 75%|███████▌  | 151/201 [03:45<00:44,  1.12it/s]INFO:__main__:Requesting https://www.hetzner.com/rechtliches/agb
INFO:__main__:Getting metadata for https://www.hetzner.com/rechtliches/agb
 76%|███████▌  | 152/201 [03:49<01:33,  1.92s/it]INFO:__main__:Requesting https://github.com/GoogleContainerTools/kubehost
INFO:__main__:Getting metadata for https://github.com/GoogleContainerTools/kubehost
 76%|███████▌  | 153/201 [03:50<01:16,  1.60s/it]INFO:__main__:Requesting https://www.radishlogic.com/kubernetes/running-minikube-in-aws-ec2-ubuntu/
INFO:__main__:Getting metadata for https://www.radishlogic.com/kubernetes/running-minikube-in-aws-ec2-ubuntu/
 77%|███████▋  | 154/201 [03:51<01:00,  1.28s/it]INFO:__main__:Requesting https://aws.amazon.com/fargate/pricing/
INFO:__main__:Getting metadata for https://aws.amazon.com/fargate/pricing/
ERROR:__main__:Could not get metadata for https://aws.amazon.com/fargate/pricing/
Traceback (most recent call last):
  File "../_scripts/crawler/crawler.py", line 94, in _get_site_title_and_description
    description = description[:450] + '...' if len(description) > 450 else description
TypeError: object of type 'NoneType' has no len()
 77%|███████▋  | 155/201 [03:51<00:47,  1.04s/it]INFO:__main__:Requesting https://github.com/kubernetes/kops
INFO:__main__:Getting metadata for https://github.com/kubernetes/kops
 78%|███████▊  | 156/201 [03:52<00:47,  1.06s/it]INFO:__main__:Requesting https://www.nytimes.com/2019/02/26/dining/homemade-yogurt-starter-south-asia.html
INFO:__main__:Getting metadata for https://www.nytimes.com/2019/02/26/dining/homemade-yogurt-starter-south-asia.html
 78%|███████▊  | 157/201 [03:52<00:35,  1.22it/s]INFO:__main__:Requesting https://www.bobsredmill.com/sourdough-starter.html
INFO:__main__:Getting metadata for https://www.bobsredmill.com/sourdough-starter.html
 79%|███████▊  | 158/201 [03:55<00:55,  1.28s/it]INFO:__main__:Requesting https://www.womenshealthmag.com/nl/voeding/feiten-fabels/a23733982/yoghurt-verschillende-soorten-gezondst/
INFO:__main__:Getting metadata for https://www.womenshealthmag.com/nl/voeding/feiten-fabels/a23733982/yoghurt-verschillende-soorten-gezondst/
 79%|███████▉  | 159/201 [03:56<00:51,  1.22s/it]INFO:__main__:Requesting https://www.ncbi.nlm.nih.gov/pmc/articles/PMC4166373/
INFO:__main__:Getting metadata for https://www.ncbi.nlm.nih.gov/pmc/articles/PMC4166373/
 80%|███████▉  | 160/201 [03:57<00:55,  1.34s/it]INFO:__main__:Requesting http://www.p01.org/defender_of_the_favicon/
INFO:__main__:Getting metadata for http://www.p01.org/defender_of_the_favicon/
 80%|████████  | 161/201 [03:59<00:54,  1.35s/it]INFO:__main__:Requesting https://github.com/jbochi/gifstreaming
INFO:__main__:Getting metadata for https://github.com/jbochi/gifstreaming
 81%|████████  | 162/201 [03:59<00:44,  1.15s/it]INFO:__main__:Requesting https://defseg.io/snavicon
INFO:__main__:Getting metadata for https://defseg.io/snavicon/
ERROR:__main__:Could not get metadata for https://defseg.io/snavicon/
Traceback (most recent call last):
  File "../_scripts/crawler/crawler.py", line 94, in _get_site_title_and_description
    description = description[:450] + '...' if len(description) > 450 else description
TypeError: object of type 'NoneType' has no len()
 81%|████████  | 163/201 [04:00<00:35,  1.08it/s]INFO:__main__:Requesting https://swordshield.pokemon.com/en-us/
INFO:__main__:Getting metadata for https://swordshield.pokemon.com/en-us/
 82%|████████▏ | 164/201 [04:00<00:27,  1.35it/s]INFO:__main__:Requesting https://worldwideweb.cern.ch/
INFO:__main__:Getting metadata for https://worldwideweb.cern.ch
 82%|████████▏ | 165/201 [04:01<00:32,  1.12it/s]INFO:__main__:Requesting https://worldwideweb.cern.ch/images/wow.jpg
INFO:__main__:Getting metadata for https://worldwideweb.cern.ch/images/wow.jpg
ERROR:__main__:Could not get metadata for https://worldwideweb.cern.ch/images/wow.jpg
Traceback (most recent call last):
  File "../_scripts/crawler/crawler.py", line 94, in _get_site_title_and_description
    description = description[:450] + '...' if len(description) > 450 else description
TypeError: object of type 'NoneType' has no len()
 83%|████████▎ | 166/201 [04:07<01:17,  2.21s/it]INFO:__main__:Requesting https://adactio.com
INFO:__main__:Getting metadata for https://adactio.com
 83%|████████▎ | 167/201 [04:07<00:56,  1.68s/it]INFO:__main__:Requesting https://worldwideweb.cern.ch/colophon/
INFO:__main__:Getting metadata for https://worldwideweb.cern.ch/colophon/
 84%|████████▎ | 168/201 [04:08<00:48,  1.48s/it]INFO:__main__:Requesting https://imgur.com/a/KWl3iUp
INFO:__main__:Getting metadata for https://imgur.com/a/KWl3iUp
ERROR:__main__:Could not get metadata for https://imgur.com/a/KWl3iUp
Traceback (most recent call last):
  File "../_scripts/crawler/crawler.py", line 94, in _get_site_title_and_description
    description = description[:450] + '...' if len(description) > 450 else description
TypeError: object of type 'NoneType' has no len()
 84%|████████▍ | 169/201 [04:09<00:40,  1.27s/it]INFO:__main__:Requesting https://github.com/djrrb/CERN-www-fonts/blob/master/README.md
 85%|████████▍ | 170/201 [04:09<00:29,  1.04it/s]INFO:__main__:Requesting http://"
ERROR:__main__:Could not reach http://"
Traceback (most recent call last):
  File "/home/travis/virtualenv/python3.6.3/lib/python3.6/site-packages/urllib3/connection.py", line 159, in _new_conn
    (self._dns_host, self.port), self.timeout, **extra_kw)
  File "/home/travis/virtualenv/python3.6.3/lib/python3.6/site-packages/urllib3/util/connection.py", line 57, in create_connection
    for res in socket.getaddrinfo(host, port, family, socket.SOCK_STREAM):
  File "/opt/python/3.6.3/lib/python3.6/socket.py", line 745, in getaddrinfo
    for res in _socket.getaddrinfo(host, port, family, type, proto, flags):
socket.gaierror: [Errno -2] Name or service not known

During handling of the above exception, another exception occurred:

Traceback (most recent call last):
  File "/home/travis/virtualenv/python3.6.3/lib/python3.6/site-packages/urllib3/connectionpool.py", line 600, in urlopen
    chunked=chunked)
  File "/home/travis/virtualenv/python3.6.3/lib/python3.6/site-packages/urllib3/connectionpool.py", line 354, in _make_request
    conn.request(method, url, **httplib_request_kw)
  File "/opt/python/3.6.3/lib/python3.6/http/client.py", line 1239, in request
    self._send_request(method, url, body, headers, encode_chunked)
  File "/opt/python/3.6.3/lib/python3.6/http/client.py", line 1285, in _send_request
    self.endheaders(body, encode_chunked=encode_chunked)
  File "/opt/python/3.6.3/lib/python3.6/http/client.py", line 1234, in endheaders
    self._send_output(message_body, encode_chunked=encode_chunked)
  File "/opt/python/3.6.3/lib/python3.6/http/client.py", line 1026, in _send_output
    self.send(msg)
  File "/opt/python/3.6.3/lib/python3.6/http/client.py", line 964, in send
    self.connect()
  File "/home/travis/virtualenv/python3.6.3/lib/python3.6/site-packages/urllib3/connection.py", line 181, in connect
    conn = self._new_conn()
  File "/home/travis/virtualenv/python3.6.3/lib/python3.6/site-packages/urllib3/connection.py", line 168, in _new_conn
    self, "Failed to establish a new connection: %s" % e)
urllib3.exceptions.NewConnectionError: <urllib3.connection.HTTPConnection object at 0x7f7ac04a6ef0>: Failed to establish a new connection: [Errno -2] Name or service not known

During handling of the above exception, another exception occurred:

Traceback (most recent call last):
  File "/home/travis/virtualenv/python3.6.3/lib/python3.6/site-packages/requests/adapters.py", line 449, in send
    timeout=timeout
  File "/home/travis/virtualenv/python3.6.3/lib/python3.6/site-packages/urllib3/connectionpool.py", line 638, in urlopen
    _stacktrace=sys.exc_info()[2])
  File "/home/travis/virtualenv/python3.6.3/lib/python3.6/site-packages/urllib3/util/retry.py", line 398, in increment
    raise MaxRetryError(_pool, url, error or ResponseError(cause))
urllib3.exceptions.MaxRetryError: HTTPConnectionPool(host='%22', port=80): Max retries exceeded with url: / (Caused by NewConnectionError('<urllib3.connection.HTTPConnection object at 0x7f7ac04a6ef0>: Failed to establish a new connection: [Errno -2] Name or service not known',))

During handling of the above exception, another exception occurred:

Traceback (most recent call last):
  File "../_scripts/crawler/crawler.py", line 210, in metafy_url
    response = requests.get(url, timeout=6, headers={'User-Agent': 'Mozilla/5.0'})
  File "/home/travis/virtualenv/python3.6.3/lib/python3.6/site-packages/requests/api.py", line 75, in get
    return request('get', url, params=params, **kwargs)
  File "/home/travis/virtualenv/python3.6.3/lib/python3.6/site-packages/requests/api.py", line 60, in request
    return session.request(method=method, url=url, **kwargs)
  File "/home/travis/virtualenv/python3.6.3/lib/python3.6/site-packages/requests/sessions.py", line 533, in request
    resp = self.send(prep, **send_kwargs)
  File "/home/travis/virtualenv/python3.6.3/lib/python3.6/site-packages/requests/sessions.py", line 646, in send
    r = adapter.send(request, **kwargs)
  File "/home/travis/virtualenv/python3.6.3/lib/python3.6/site-packages/requests/adapters.py", line 516, in send
    raise ConnectionError(e, request=request)
requests.exceptions.ConnectionError: HTTPConnectionPool(host='%22', port=80): Max retries exceeded with url: / (Caused by NewConnectionError('<urllib3.connection.HTTPConnection object at 0x7f7ac04a6ef0>: Failed to establish a new connection: [Errno -2] Name or service not known',))
INFO:__main__:Requesting http://blog.lareviewofbooks.org/essays/self-publishing-pleased-brief-glimpse-life-small-town-bookseller-writer/
INFO:__main__:Getting metadata for http://blog.lareviewofbooks.org/essays/self-publishing-pleased-brief-glimpse-life-small-town-bookseller-writer/
 86%|████████▌ | 172/201 [04:11<00:28,  1.02it/s]INFO:__main__:Requesting https://www.bookweb.org/for-the-record
INFO:__main__:Getting metadata for https://www.bookweb.org/for-the-record
ERROR:__main__:Could not get metadata for https://www.bookweb.org/for-the-record
Traceback (most recent call last):
  File "../_scripts/crawler/crawler.py", line 94, in _get_site_title_and_description
    description = description[:450] + '...' if len(description) > 450 else description
TypeError: object of type 'NoneType' has no len()
 86%|████████▌ | 173/201 [04:12<00:22,  1.27it/s]INFO:__main__:Requesting https://redislabs.com/blog/redis-turns-10/
INFO:__main__:Getting metadata for https://redislabs.com/blog/redis-turns-10/
 87%|████████▋ | 174/201 [04:13<00:22,  1.19it/s]INFO:__main__:Requesting http://www.oss4gov.org/manifesto
INFO:__main__:Getting metadata for http://oss4gov.org/manifesto
 87%|████████▋ | 175/201 [04:14<00:29,  1.12s/it]INFO:__main__:Requesting https://18f.gsa.gov/
INFO:__main__:Getting metadata for https://18f.gsa.gov
 88%|████████▊ | 176/201 [04:15<00:21,  1.15it/s]INFO:__main__:Requesting https://18f.gsa.gov/open-source-policy/
INFO:__main__:Getting metadata for https://18f.gsa.gov/open-source-policy/
 88%|████████▊ | 177/201 [04:15<00:17,  1.38it/s]INFO:__main__:Requesting https://github.com/18F
INFO:__main__:Getting metadata for https://github.com/18F
 89%|████████▊ | 178/201 [04:16<00:20,  1.15it/s]INFO:__main__:Requesting https://news.ycombinator.com/front?day=2009-02-25
INFO:__main__:Getting metadata for https://news.ycombinator.com/front?day=2009-02-25
ERROR:__main__:Could not get metadata for https://news.ycombinator.com/front?day=2009-02-25
Traceback (most recent call last):
  File "../_scripts/crawler/crawler.py", line 94, in _get_site_title_and_description
    description = description[:450] + '...' if len(description) > 450 else description
TypeError: object of type 'NoneType' has no len()
 89%|████████▉ | 179/201 [04:19<00:30,  1.39s/it]INFO:__main__:Requesting https://news.ycombinator.com/front?day=2019-02-25
INFO:__main__:Getting metadata for https://news.ycombinator.com/front?day=2019-02-25
ERROR:__main__:Could not get metadata for https://news.ycombinator.com/front?day=2019-02-25
Traceback (most recent call last):
  File "../_scripts/crawler/crawler.py", line 94, in _get_site_title_and_description
    description = description[:450] + '...' if len(description) > 450 else description
TypeError: object of type 'NoneType' has no len()
 90%|████████▉ | 180/201 [04:21<00:35,  1.68s/it]INFO:__main__:Requesting https://en.wikipedia.org/wiki/Relational_algebra
INFO:__main__:Getting metadata for https://en.wikipedia.org/wiki/Relational_algebra
 90%|█████████ | 181/201 [04:24<00:37,  1.88s/it]INFO:__main__:Requesting http://antirez.com/news/122
INFO:__main__:Getting metadata for http://antirez.com/news/122
ERROR:__main__:Could not get metadata for http://antirez.com/news/122
Traceback (most recent call last):
  File "../_scripts/crawler/crawler.py", line 94, in _get_site_title_and_description
    description = description[:450] + '...' if len(description) > 450 else description
TypeError: object of type 'NoneType' has no len()
 91%|█████████ | 182/201 [04:25<00:35,  1.85s/it]INFO:__main__:Requesting https://gist.github.com/antirez/6ca04dd191bdb82aad9fb241013e88a8
INFO:__main__:Getting metadata for https://gist.github.com/antirez/6ca04dd191bdb82aad9fb241013e88a8
 91%|█████████ | 183/201 [04:26<00:28,  1.58s/it]INFO:__main__:Requesting https://redis.io/topics/pubsub
INFO:__main__:Getting metadata for https://redis.io/topics/pubsub
 92%|█████████▏| 184/201 [04:28<00:29,  1.76s/it]INFO:__main__:Requesting https://www.pearson.com/us/higher-education/program/Ousterhout-Tcl-and-the-Tk-Toolkit-2nd-Edition/PGM23076.html
INFO:__main__:Getting metadata for https://www.pearson.com/us/higher-education/program/Ousterhout-Tcl-and-the-Tk-Toolkit-2nd-Edition/PGM23076.html
ERROR:__main__:Could not get metadata for https://www.pearson.com/us/higher-education/program/Ousterhout-Tcl-and-the-Tk-Toolkit-2nd-Edition/PGM23076.html
Traceback (most recent call last):
  File "../_scripts/crawler/crawler.py", line 93, in _get_site_title_and_description
    title, description, _ = web_preview(url, content=content)
  File "/home/travis/virtualenv/python3.6.3/lib/python3.6/site-packages/webpreview/previews.py", line 195, in web_preview
    content=content)
  File "/home/travis/virtualenv/python3.6.3/lib/python3.6/site-packages/webpreview/previews.py", line 174, in __init__
    super(TwitterCard, self).__init__(*args, **kwargs)
  File "/home/travis/virtualenv/python3.6.3/lib/python3.6/site-packages/webpreview/previews.py", line 132, in __init__
    self._set_properties()
  File "/home/travis/virtualenv/python3.6.3/lib/python3.6/site-packages/webpreview/previews.py", line 152, in _set_properties
    if property_meta and property_meta['content'] != "":
  File "/home/travis/virtualenv/python3.6.3/lib/python3.6/site-packages/bs4/element.py", line 1016, in __getitem__
    return self.attrs[key]
KeyError: 'content'
 92%|█████████▏| 185/201 [04:31<00:31,  1.95s/it]INFO:__main__:Requesting https://tcl.apache.org/rivet/
INFO:__main__:Getting metadata for https://tcl.apache.org/rivet/
 93%|█████████▎| 186/201 [04:34<00:32,  2.18s/it]INFO:__main__:Requesting http://antirez.com/articoli/tclmisunderstood.html
INFO:__main__:Getting metadata for http://antirez.com/articoli/tclmisunderstood.html
 93%|█████████▎| 187/201 [04:35<00:26,  1.88s/it]INFO:__main__:Requesting http://jim.tcl.tk/index.html/doc/www/www/index.html
INFO:__main__:Getting metadata for http://jim.tcl.tk/index.html/doc/www/www/index.html
 94%|█████████▎| 188/201 [04:35<00:18,  1.46s/it]INFO:__main__:Requesting https://en.m.wikipedia.org/wiki/D._Richard_Hipp
INFO:__main__:Getting metadata for https://en.m.wikipedia.org/wiki/D._Richard_Hipp
 94%|█████████▍| 189/201 [04:36<00:14,  1.23s/it]INFO:__main__:Requesting https://www.tcl.tk/community/tcl2017/assets/talk93/Paper.html
INFO:__main__:Getting metadata for https://www.tcl.tk/community/tcl2017/assets/talk93/Paper.html
 95%|█████████▍| 190/201 [04:37<00:12,  1.16s/it]INFO:__main__:Requesting https://www.dbms2.com/2008/02/18/mike-stonebraker-calls-for-the-complete-destruction-of-the-old-dbms-order/
INFO:__main__:Getting metadata for https://www.dbms2.com/2008/02/18/mike-stonebraker-calls-for-the-complete-destruction-of-the-old-dbms-order/
 95%|█████████▌| 191/201 [04:41<00:20,  2.03s/it]INFO:__main__:Requesting https://www.bleepingcomputer.com/news/security/around-75-percent-of-open-redis-servers-are-infected-with-malware/
INFO:__main__:Getting metadata for https://www.bleepingcomputer.com/news/security/around-75-percent-of-open-redis-servers-are-infected-with-malware/
 96%|█████████▌| 192/201 [04:42<00:16,  1.84s/it]INFO:__main__:Requesting http://antirez.com/news/96
INFO:__main__:Getting metadata for http://antirez.com/news/96
ERROR:__main__:Could not get metadata for http://antirez.com/news/96
Traceback (most recent call last):
  File "../_scripts/crawler/crawler.py", line 94, in _get_site_title_and_description
    description = description[:450] + '...' if len(description) > 450 else description
TypeError: object of type 'NoneType' has no len()
 96%|█████████▌| 193/201 [04:43<00:12,  1.62s/it]INFO:__main__:Requesting https://goodformcode.com
INFO:__main__:Getting metadata for https://goodformcode.com
 97%|█████████▋| 194/201 [04:44<00:08,  1.22s/it]INFO:__main__:Requesting https://www.zdnet.com/article/windows-10-new-study-shows-home-edition-users-are-baffled-by-updates/
INFO:__main__:Getting metadata for https://www.zdnet.com/article/windows-10-new-study-shows-home-edition-users-are-baffled-by-updates/
 97%|█████████▋| 195/201 [04:44<00:06,  1.00s/it]INFO:__main__:Requesting https://support.microsoft.com/en-us/help/3159635/windows-10-update-assistant
INFO:__main__:Getting metadata for https://support.microsoft.com/en-us/help/3159635/windows-10-update-assistant
 98%|█████████▊| 196/201 [04:45<00:05,  1.03s/it]INFO:__main__:Requesting https://mouse-jiggler.en.uptodown.com/windows
INFO:__main__:Getting metadata for https://mouse-jiggler.en.uptodown.com/windows
 98%|█████████▊| 197/201 [04:46<00:03,  1.16it/s]INFO:__main__:Requesting https://www.udse.de/en/windows-10-reboot-blocker
INFO:__main__:Getting metadata for https://www.udse.de/en/windows-10-reboot-blocker
 99%|█████████▊| 198/201 [04:51<00:06,  2.05s/it]INFO:__main__:Requesting https://arstechnica.com/information-technology/2013/12/exponential-algorithm-making-windows-xp-miserable-could-be-fixed/
INFO:__main__:Getting metadata for https://arstechnica.com/information-technology/2013/12/exponential-algorithm-making-windows-xp-miserable-could-be-fixed/
 99%|█████████▉| 199/201 [04:51<00:02,  1.48s/it]INFO:__main__:Requesting https://answers.microsoft.com/en-us/windows/forum/windows_10-update/windows-10-1809-update-deleted-all-files-from/ff608374-2686-4a08-a4c2-caa4caa6d4e1?auth=1
INFO:__main__:Getting metadata for https://answers.microsoft.com/en-us/windows/forum/windows_10-update/windows-10-1809-update-deleted-all-files-from/ff608374-2686-4a08-a4c2-caa4caa6d4e1?auth=1
100%|█████████▉| 200/201 [04:52<00:01,  1.39s/it]INFO:__main__:Requesting https://sensorstechforum.com/smart-homes-at-risk-to-hackers/
INFO:__main__:Getting metadata for https://sensorstechforum.com/smart-homes-at-risk-to-hackers/
100%|██████████| 201/201 [04:54<00:00,  1.59s/it]
