INFO:__main__:Get urls from stories
  0%|          | 0/30 [00:00<?, ?it/s]  3%|▎         | 1/30 [00:01<00:41,  1.42s/it]  7%|▋         | 2/30 [00:01<00:30,  1.10s/it] 10%|█         | 3/30 [00:02<00:25,  1.08it/s] 17%|█▋        | 5/30 [00:02<00:17,  1.44it/s] 20%|██        | 6/30 [00:04<00:28,  1.18s/it] 23%|██▎       | 7/30 [00:06<00:28,  1.25s/it] 30%|███       | 9/30 [00:10<00:32,  1.52s/it] 37%|███▋      | 11/30 [00:16<00:38,  2.01s/it] 40%|████      | 12/30 [00:18<00:32,  1.80s/it] 43%|████▎     | 13/30 [00:18<00:22,  1.31s/it] 47%|████▋     | 14/30 [00:18<00:16,  1.06s/it] 50%|█████     | 15/30 [00:19<00:13,  1.12it/s] 53%|█████▎    | 16/30 [00:19<00:10,  1.32it/s] 60%|██████    | 18/30 [00:20<00:07,  1.70it/s] 67%|██████▋   | 20/30 [00:23<00:08,  1.15it/s] 70%|███████   | 21/30 [00:23<00:06,  1.43it/s] 80%|████████  | 24/30 [00:24<00:03,  1.61it/s] 83%|████████▎ | 25/30 [00:27<00:05,  1.11s/it] 87%|████████▋ | 26/30 [00:27<00:03,  1.07it/s] 90%|█████████ | 27/30 [00:28<00:02,  1.23it/s] 93%|█████████▎| 28/30 [00:28<00:01,  1.43it/s]100%|██████████| 30/30 [00:28<00:00,  1.05it/s]
  0%|          | 0/172 [00:00<?, ?it/s]INFO:__main__:Requesting https://www.npr.org/sections/health-shots/2019/02/26/696321475/cancer-complications-confusing-bills-maddening-errors-and-endless-phone-calls
INFO:__main__:Getting metadata for https://www.npr.org/sections/health-shots/2019/02/26/696321475/cancer-complications-confusing-bills-maddening-errors-and-endless-phone-calls
  1%|          | 1/172 [00:00<00:40,  4.26it/s]INFO:__main__:Requesting https://en.wikipedia.org/wiki/Thalidomide
INFO:__main__:Getting metadata for https://en.wikipedia.org/wiki/Thalidomide
  1%|          | 2/172 [00:02<02:24,  1.17it/s]INFO:__main__:Requesting https://en.wikipedia.org/wiki/Frances_Oldham_Kelsey
INFO:__main__:Getting metadata for https://en.wikipedia.org/wiki/Frances_Oldham_Kelsey
  2%|▏         | 3/172 [00:03<02:39,  1.06it/s]INFO:__main__:Requesting https://en.m.wikipedia.org/wiki/Prescription_costs
INFO:__main__:Getting metadata for https://en.m.wikipedia.org/wiki/Prescription_costs
  2%|▏         | 4/172 [00:04<02:44,  1.02it/s]INFO:__main__:Requesting https://www.forbes.com/sites/quora/2017/06/13/why-the-us-has-better-cancer-survival-rates-than-the-rest-of-the-world/#37e92baa4b67
INFO:__main__:Getting metadata for https://www.forbes.com/sites/quora/2017/06/13/why-the-us-has-better-cancer-survival-rates-than-the-rest-of-the-world/#37e92baa4b67
  3%|▎         | 5/172 [00:07<03:51,  1.39s/it]INFO:__main__:Requesting https://www.scientificamerican.com/article/how-the-u-s-pays-3-times-more-for-drugs/
INFO:__main__:Getting metadata for https://www.scientificamerican.com/article/how-the-u-s-pays-3-times-more-for-drugs/
  3%|▎         | 6/172 [00:07<03:19,  1.20s/it]INFO:__main__:Requesting https://www.forbes.com/sites/maggiemcgrath/2016/01/06/63-of-americans-dont-have-enough-savings-to-cover-a-500-emergency/#14c251a34e0d
INFO:__main__:Getting metadata for https://www.forbes.com/sites/maggiemcgrath/2016/01/06/63-of-americans-dont-have-enough-savings-to-cover-a-500-emergency/#14c251a34e0d
  4%|▍         | 7/172 [00:08<02:33,  1.08it/s]INFO:__main__:Requesting https://slate.com/technology/2016/04/biomedicine-facing-a-worse-replication-crisis-than-the-one-plaguing-psychology.html
INFO:__main__:Getting metadata for https://slate.com/technology/2016/04/biomedicine-facing-a-worse-replication-crisis-than-the-one-plaguing-psychology.html
  5%|▍         | 8/172 [00:10<03:38,  1.33s/it]INFO:__main__:Requesting http://www.ascopost.com/issues/may-25-2016/the-arrival-of-generic-imatinib-into-the-us-market-an-educational-event/
INFO:__main__:Getting metadata for http://www.ascopost.com/issues/may-25-2016/the-arrival-of-generic-imatinib-into-the-us-market-an-educational-event/
  5%|▌         | 9/172 [00:11<03:37,  1.34s/it]INFO:__main__:Requesting https://www.wnycstudios.org/story/worth
INFO:__main__:Getting metadata for https://www.wnycstudios.org/story/worth
  6%|▌         | 10/172 [00:12<02:57,  1.09s/it]INFO:__main__:Requesting https://thenib.com/americans-are-drowning-in-debt
INFO:__main__:Getting metadata for https://thenib.com/americans-are-drowning-in-debt
  6%|▋         | 11/172 [00:12<02:33,  1.05it/s]INFO:__main__:Requesting https://text.npr.org/s.php?sId=696321475
INFO:__main__:Getting metadata for https://text.npr.org/s.php?sId=696321475
ERROR:__main__:Could not get metadata for https://text.npr.org/s.php?sId=696321475
Traceback (most recent call last):
  File "../_scripts/crawler/crawler.py", line 94, in _get_site_title_and_description
    description = description[:450] + '...' if len(description) > 450 else description
TypeError: object of type 'NoneType' has no len()
  7%|▋         | 12/172 [00:13<02:28,  1.08it/s]INFO:__main__:Requesting https://www.policymed.com/2014/12/a-tough-road-cost-to-develop-one-new-drug-is-26-billion-approval-rate-for-drugs-entering-clinical-de.html
INFO:__main__:Getting metadata for https://www.policymed.com/2014/12/a-tough-road-cost-to-develop-one-new-drug-is-26-billion-approval-rate-for-drugs-entering-clinical-de.html
  8%|▊         | 13/172 [00:14<02:06,  1.26it/s]INFO:__main__:Requesting https://www.cbsnews.com/news/most-americans-cant-afford-a-500-emergency-expense/
INFO:__main__:Getting metadata for https://www.cbsnews.com/news/most-americans-cant-afford-a-500-emergency-expense/
  8%|▊         | 14/172 [00:14<01:50,  1.43it/s]INFO:__main__:Requesting https://redalemeden.com/blog/2019/we-need-chrome-no-more
INFO:__main__:Getting metadata for https://redalemeden.com/blog/2019/we-need-chrome-no-more/
  9%|▊         | 15/172 [00:15<02:03,  1.27it/s]INFO:__main__:Requesting https://www.adsoftheworld.com/media/film/google_chrome_speed_tests
INFO:__main__:Getting metadata for https://www.adsoftheworld.com/media/film/google_chrome_speed_tests
ERROR:__main__:Could not get metadata for https://www.adsoftheworld.com/media/film/google_chrome_speed_tests
Traceback (most recent call last):
  File "../_scripts/crawler/crawler.py", line 94, in _get_site_title_and_description
    description = description[:450] + '...' if len(description) > 450 else description
TypeError: object of type 'NoneType' has no len()
  9%|▉         | 16/172 [00:16<02:12,  1.18it/s]INFO:__main__:Requesting https://www.lowtechmagazine.com/
INFO:__main__:Getting metadata for https://www.lowtechmagazine.com
 10%|▉         | 17/172 [00:17<02:01,  1.28it/s]INFO:__main__:Requesting https://www.lowtechmagazine.com/2019/02/heat-your-house-with-a-water-brake-windmill.html
INFO:__main__:Getting metadata for https://www.lowtechmagazine.com/2019/02/heat-your-house-with-a-water-brake-windmill.html
 10%|█         | 18/172 [00:17<01:51,  1.38it/s]INFO:__main__:Requesting https://en.wikipedia.org/wiki/Mechanical_equivalent_of_heat
INFO:__main__:Getting metadata for https://en.wikipedia.org/wiki/Mechanical_equivalent_of_heat
 11%|█         | 19/172 [00:18<02:01,  1.26it/s]INFO:__main__:Requesting https://www.youtube.com/watch?v=GjcOobt9Ef8
INFO:__main__:Getting metadata for https://www.youtube.com/watch?v=GjcOobt9Ef8
 12%|█▏        | 20/172 [00:19<02:13,  1.14it/s]INFO:__main__:Requesting https://www.energy.gov/eere/solar/articles/solar-radiation-basics
 12%|█▏        | 21/172 [00:20<01:41,  1.49it/s]INFO:__main__:Requesting https://www.nrel.gov/gis/images/map_pv_us_january_dec2008.jpg
INFO:__main__:Getting metadata for https://www.nrel.gov/gis/images/map_pv_us_january_dec2008.jpg
ERROR:__main__:Could not get metadata for https://www.nrel.gov/gis/images/map_pv_us_january_dec2008.jpg
Traceback (most recent call last):
  File "../_scripts/crawler/crawler.py", line 94, in _get_site_title_and_description
    description = description[:450] + '...' if len(description) > 450 else description
TypeError: object of type 'NoneType' has no len()
 13%|█▎        | 22/172 [00:30<08:38,  3.46s/it]INFO:__main__:Requesting https://www.nrel.gov/gis/images/map_pv_us_july_dec2008.jpg
INFO:__main__:Getting metadata for https://www.nrel.gov/gis/images/map_pv_us_july_dec2008.jpg
ERROR:__main__:Could not get metadata for https://www.nrel.gov/gis/images/map_pv_us_july_dec2008.jpg
Traceback (most recent call last):
  File "../_scripts/crawler/crawler.py", line 94, in _get_site_title_and_description
    description = description[:450] + '...' if len(description) > 450 else description
TypeError: object of type 'NoneType' has no len()
 13%|█▎        | 23/172 [00:39<12:52,  5.19s/it]INFO:__main__:Requesting https://en.wikipedia.org/wiki/District_heating
INFO:__main__:Getting metadata for https://en.wikipedia.org/wiki/District_heating
 14%|█▍        | 24/172 [00:41<10:14,  4.15s/it]INFO:__main__:Requesting https://www.lowtechmagazine.com/2013/03/the-mechanical-transmission-of-power-3-wire-ropes.html
INFO:__main__:Getting metadata for https://www.lowtechmagazine.com/2013/03/the-mechanical-transmission-of-power-3-wire-ropes.html
 15%|█▍        | 25/172 [00:42<08:06,  3.31s/it]INFO:__main__:Requesting https://www.gremlin.com/blog/introducing-gremlin-free/
INFO:__main__:Getting metadata for https://www.gremlin.com/blog/introducing-gremlin-free/
 15%|█▌        | 26/172 [00:43<06:30,  2.68s/it]INFO:__main__:Requesting https://www.secbsd.org/
INFO:__main__:Getting metadata for https://www.secbsd.org
ERROR:__main__:Could not get metadata for https://www.secbsd.org
Traceback (most recent call last):
  File "../_scripts/crawler/crawler.py", line 94, in _get_site_title_and_description
    description = description[:450] + '...' if len(description) > 450 else description
TypeError: object of type 'NoneType' has no len()
 16%|█▌        | 27/172 [00:46<06:56,  2.87s/it]INFO:__main__:Requesting https://redislabs.com/blog/redis-turns-10/
INFO:__main__:Getting metadata for https://redislabs.com/blog/redis-turns-10/
 16%|█▋        | 28/172 [00:48<05:39,  2.36s/it]INFO:__main__:Requesting http://www.oss4gov.org/manifesto
INFO:__main__:Getting metadata for http://oss4gov.org/manifesto
 17%|█▋        | 29/172 [00:49<05:10,  2.17s/it]INFO:__main__:Requesting https://18f.gsa.gov/
INFO:__main__:Getting metadata for https://18f.gsa.gov
 17%|█▋        | 30/172 [00:50<03:52,  1.64s/it]INFO:__main__:Requesting https://18f.gsa.gov/open-source-policy/
INFO:__main__:Getting metadata for https://18f.gsa.gov/open-source-policy/
 18%|█▊        | 31/172 [00:50<02:59,  1.27s/it]INFO:__main__:Requesting https://github.com/18F
INFO:__main__:Getting metadata for https://github.com/18F
 19%|█▊        | 32/172 [00:51<02:52,  1.23s/it]INFO:__main__:Requesting https://news.ycombinator.com/front?day=2009-02-25
INFO:__main__:Getting metadata for https://news.ycombinator.com/front?day=2009-02-25
ERROR:__main__:Could not get metadata for https://news.ycombinator.com/front?day=2009-02-25
Traceback (most recent call last):
  File "../_scripts/crawler/crawler.py", line 94, in _get_site_title_and_description
    description = description[:450] + '...' if len(description) > 450 else description
TypeError: object of type 'NoneType' has no len()
 19%|█▉        | 33/172 [00:54<03:36,  1.55s/it]INFO:__main__:Requesting https://news.ycombinator.com/front?day=2019-02-25
INFO:__main__:Getting metadata for https://news.ycombinator.com/front?day=2019-02-25
ERROR:__main__:Could not get metadata for https://news.ycombinator.com/front?day=2019-02-25
Traceback (most recent call last):
  File "../_scripts/crawler/crawler.py", line 94, in _get_site_title_and_description
    description = description[:450] + '...' if len(description) > 450 else description
TypeError: object of type 'NoneType' has no len()
 20%|█▉        | 34/172 [00:56<04:07,  1.79s/it]INFO:__main__:Requesting https://en.wikipedia.org/wiki/Relational_algebra
INFO:__main__:Getting metadata for https://en.wikipedia.org/wiki/Relational_algebra
 20%|██        | 35/172 [00:58<04:18,  1.89s/it]INFO:__main__:Requesting http://antirez.com/news/122
INFO:__main__:Getting metadata for http://antirez.com/news/122
ERROR:__main__:Could not get metadata for http://antirez.com/news/122
Traceback (most recent call last):
  File "../_scripts/crawler/crawler.py", line 94, in _get_site_title_and_description
    description = description[:450] + '...' if len(description) > 450 else description
TypeError: object of type 'NoneType' has no len()
 21%|██        | 36/172 [00:59<03:47,  1.68s/it]INFO:__main__:Requesting https://gist.github.com/antirez/6ca04dd191bdb82aad9fb241013e88a8
INFO:__main__:Getting metadata for https://gist.github.com/antirez/6ca04dd191bdb82aad9fb241013e88a8
 22%|██▏       | 37/172 [01:01<03:34,  1.59s/it]INFO:__main__:Requesting https://redis.io/topics/pubsub
INFO:__main__:Getting metadata for https://redis.io/topics/pubsub
 22%|██▏       | 38/172 [01:03<03:55,  1.76s/it]INFO:__main__:Requesting https://www.pearson.com/us/higher-education/program/Ousterhout-Tcl-and-the-Tk-Toolkit-2nd-Edition/PGM23076.html
INFO:__main__:Getting metadata for https://www.pearson.com/us/higher-education/program/Ousterhout-Tcl-and-the-Tk-Toolkit-2nd-Edition/PGM23076.html
ERROR:__main__:Could not get metadata for https://www.pearson.com/us/higher-education/program/Ousterhout-Tcl-and-the-Tk-Toolkit-2nd-Edition/PGM23076.html
Traceback (most recent call last):
  File "../_scripts/crawler/crawler.py", line 93, in _get_site_title_and_description
    title, description, _ = web_preview(url, content=content)
  File "/home/travis/virtualenv/python3.6.3/lib/python3.6/site-packages/webpreview/previews.py", line 195, in web_preview
    content=content)
  File "/home/travis/virtualenv/python3.6.3/lib/python3.6/site-packages/webpreview/previews.py", line 174, in __init__
    super(TwitterCard, self).__init__(*args, **kwargs)
  File "/home/travis/virtualenv/python3.6.3/lib/python3.6/site-packages/webpreview/previews.py", line 132, in __init__
    self._set_properties()
  File "/home/travis/virtualenv/python3.6.3/lib/python3.6/site-packages/webpreview/previews.py", line 152, in _set_properties
    if property_meta and property_meta['content'] != "":
  File "/home/travis/virtualenv/python3.6.3/lib/python3.6/site-packages/bs4/element.py", line 1016, in __getitem__
    return self.attrs[key]
KeyError: 'content'
 23%|██▎       | 39/172 [01:05<04:08,  1.87s/it]INFO:__main__:Requesting https://tcl.apache.org/rivet/
INFO:__main__:Getting metadata for https://tcl.apache.org/rivet/
 23%|██▎       | 40/172 [01:08<04:41,  2.13s/it]INFO:__main__:Requesting http://antirez.com/articoli/tclmisunderstood.html
INFO:__main__:Getting metadata for http://antirez.com/articoli/tclmisunderstood.html
 24%|██▍       | 41/172 [01:09<03:58,  1.82s/it]INFO:__main__:Requesting http://jim.tcl.tk/index.html/doc/www/www/index.html
INFO:__main__:Getting metadata for http://jim.tcl.tk/index.html/doc/www/www/index.html
 24%|██▍       | 42/172 [01:09<03:04,  1.42s/it]INFO:__main__:Requesting https://en.m.wikipedia.org/wiki/D._Richard_Hipp
INFO:__main__:Getting metadata for https://en.m.wikipedia.org/wiki/D._Richard_Hipp
 25%|██▌       | 43/172 [01:10<02:36,  1.22s/it]INFO:__main__:Requesting https://www.tcl.tk/community/tcl2017/assets/talk93/Paper.html
INFO:__main__:Getting metadata for https://www.tcl.tk/community/tcl2017/assets/talk93/Paper.html
 26%|██▌       | 44/172 [01:11<02:26,  1.15s/it]INFO:__main__:Requesting https://www.dbms2.com/2008/02/18/mike-stonebraker-calls-for-the-complete-destruction-of-the-old-dbms-order/
INFO:__main__:Getting metadata for https://www.dbms2.com/2008/02/18/mike-stonebraker-calls-for-the-complete-destruction-of-the-old-dbms-order/
 26%|██▌       | 45/172 [01:15<04:16,  2.02s/it]INFO:__main__:Requesting https://www.bleepingcomputer.com/news/security/around-75-percent-of-open-redis-servers-are-infected-with-malware/
INFO:__main__:Getting metadata for https://www.bleepingcomputer.com/news/security/around-75-percent-of-open-redis-servers-are-infected-with-malware/
 27%|██▋       | 46/172 [01:17<04:03,  1.93s/it]INFO:__main__:Requesting http://antirez.com/news/96
INFO:__main__:Getting metadata for http://antirez.com/news/96
ERROR:__main__:Could not get metadata for http://antirez.com/news/96
Traceback (most recent call last):
  File "../_scripts/crawler/crawler.py", line 94, in _get_site_title_and_description
    description = description[:450] + '...' if len(description) > 450 else description
TypeError: object of type 'NoneType' has no len()
 27%|██▋       | 47/172 [01:20<04:46,  2.29s/it]INFO:__main__:Requesting https://goodformcode.com
INFO:__main__:Getting metadata for https://goodformcode.com
 28%|██▊       | 48/172 [01:20<03:30,  1.69s/it]INFO:__main__:Requesting https://decryptmedia.com/5414/alleged-coinomi-exploit-concern
INFO:__main__:Getting metadata for https://decryptmedia.com/5414/alleged-coinomi-exploit-concern
 28%|██▊       | 49/172 [01:20<02:35,  1.26s/it]INFO:__main__:Requesting https://www.bankofamerica.com/privacy/faq/data-compromise-faq.go
INFO:__main__:Getting metadata for https://www.bankofamerica.com/privacy/faq/data-compromise-faq.go
 29%|██▉       | 50/172 [01:22<02:54,  1.43s/it]INFO:__main__:Requesting https://www.avoid-coinomi.com/
INFO:__main__:Getting metadata for https://www.avoid-coinomi.com
ERROR:__main__:Could not get metadata for https://www.avoid-coinomi.com
Traceback (most recent call last):
  File "../_scripts/crawler/crawler.py", line 94, in _get_site_title_and_description
    description = description[:450] + '...' if len(description) > 450 else description
TypeError: object of type 'NoneType' has no len()
 30%|██▉       | 51/172 [01:25<03:46,  1.87s/it]INFO:__main__:Requesting https://medium.com/coinomi/official-statement-on-spell-check-findings-547ca348676b
INFO:__main__:Getting metadata for https://medium.com/coinomi/official-statement-on-spell-check-findings-547ca348676b
 30%|███       | 52/172 [01:26<02:55,  1.46s/it]INFO:__main__:Requesting https://developer.android.com/reference/android/widget/EditText
INFO:__main__:Getting metadata for https://developer.android.com/reference/android/widget/EditText
ERROR:__main__:Could not get metadata for https://developer.android.com/reference/android/widget/EditText
Traceback (most recent call last):
  File "../_scripts/crawler/crawler.py", line 94, in _get_site_title_and_description
    description = description[:450] + '...' if len(description) > 450 else description
TypeError: object of type 'NoneType' has no len()
 31%|███       | 53/172 [01:31<05:11,  2.62s/it]INFO:__main__:Requesting https://delta.chat/en/
INFO:__main__:Getting metadata for https://delta.chat/en/
 31%|███▏      | 54/172 [01:32<04:06,  2.09s/it]INFO:__main__:Requesting https://www.coi-dev.org/
INFO:__main__:Getting metadata for https://www.coi-dev.org
ERROR:__main__:Could not get metadata for https://www.coi-dev.org
Traceback (most recent call last):
  File "../_scripts/crawler/crawler.py", line 94, in _get_site_title_and_description
    description = description[:450] + '...' if len(description) > 450 else description
TypeError: object of type 'NoneType' has no len()
 32%|███▏      | 55/172 [01:33<03:29,  1.79s/it]INFO:__main__:Requesting https://k3s.io
INFO:__main__:Getting metadata for https://k3s.io
 33%|███▎      | 56/172 [01:34<02:49,  1.46s/it]INFO:__main__:Requesting https://en.wikipedia.org/wiki/Erlang_(programming_language)
INFO:__main__:Getting metadata for https://en.wikipedia.org/wiki/Erlang_(programming_language)
 33%|███▎      | 57/172 [01:35<02:38,  1.38s/it]INFO:__main__:Requesting http://erlang.org/pipermail/erlang-questions/2008-October/039261.html
INFO:__main__:Getting metadata for http://erlang.org/pipermail/erlang-questions/2008-October/039261.html
 34%|███▎      | 58/172 [01:38<03:24,  1.79s/it]INFO:__main__:Requesting https://fosdem.org/2019/schedule/event/hw_gitlab_ci_arduino/
INFO:__main__:Getting metadata for https://fosdem.org/2019/schedule/event/hw_gitlab_ci_arduino/
ERROR:__main__:Could not get metadata for https://fosdem.org/2019/schedule/event/hw_gitlab_ci_arduino/
Traceback (most recent call last):
  File "../_scripts/crawler/crawler.py", line 94, in _get_site_title_and_description
    description = description[:450] + '...' if len(description) > 450 else description
TypeError: object of type 'NoneType' has no len()
 34%|███▍      | 59/172 [01:39<03:02,  1.61s/it]INFO:__main__:Requesting https://github.com/rancher/k3s/blob/master/README.md#what-is-this
INFO:__main__:Getting metadata for https://github.com/rancher/k3s/blob/master/README.md#what-is-this
 35%|███▍      | 60/172 [01:40<02:32,  1.36s/it]INFO:__main__:Requesting https://github.com/rancher/k3s/blob/master/README.md#server-ha
INFO:__main__:Getting metadata for https://github.com/rancher/k3s/blob/master/README.md#server-ha
 35%|███▌      | 61/172 [01:41<02:36,  1.41s/it]INFO:__main__:Requesting https://github.com/rancher/k3s/search?q=ingress&type=Commits
INFO:__main__:Getting metadata for https://github.com/rancher/k3s/search?q=ingress&type=Commits
 36%|███▌      | 62/172 [01:42<02:21,  1.29s/it]INFO:__main__:Requesting https://twitter.com/kelseyhightower/status/935252923721793536
INFO:__main__:Getting metadata for https://twitter.com/kelseyhightower/status/935252923721793536
 37%|███▋      | 63/172 [01:43<02:16,  1.26s/it]INFO:__main__:Requesting https://youtu.be/mMpZpa7uUSk
INFO:__main__:Getting metadata for https://www.youtube.com/watch?v=mMpZpa7uUSk&feature=youtu.be
 37%|███▋      | 64/172 [01:44<02:02,  1.14s/it]INFO:__main__:Requesting https://landscape.cncf.io/category=certified-kubernetes-distribution,certified-kubernetes-hosted,certified-kubernetes-installer&format=card-mode&grouping=category&selected=k3s
INFO:__main__:Getting metadata for https://landscape.cncf.io/category=certified-kubernetes-distribution,certified-kubernetes-hosted,certified-kubernetes-installer&format=card-mode&grouping=category&selected=k3s
ERROR:__main__:Could not get metadata for https://landscape.cncf.io/category=certified-kubernetes-distribution,certified-kubernetes-hosted,certified-kubernetes-installer&format=card-mode&grouping=category&selected=k3s
Traceback (most recent call last):
  File "../_scripts/crawler/crawler.py", line 94, in _get_site_title_and_description
    description = description[:450] + '...' if len(description) > 450 else description
TypeError: object of type 'NoneType' has no len()
 38%|███▊      | 65/172 [01:44<01:35,  1.12it/s]INFO:__main__:Requesting http://www.pidramble.com
INFO:__main__:Getting metadata for http://www.pidramble.com
 38%|███▊      | 66/172 [01:45<01:16,  1.38it/s]INFO:__main__:Requesting https://www.youtube.com/watch?v=5-5t672vFi4
INFO:__main__:Getting metadata for https://www.youtube.com/watch?v=5-5t672vFi4
 39%|███▉      | 67/172 [01:46<01:24,  1.24it/s]INFO:__main__:Requesting https://www.sqlite.org/famous.html
INFO:__main__:Getting metadata for https://www.sqlite.org/famous.html
ERROR:__main__:Could not get metadata for https://www.sqlite.org/famous.html
Traceback (most recent call last):
  File "../_scripts/crawler/crawler.py", line 94, in _get_site_title_and_description
    description = description[:450] + '...' if len(description) > 450 else description
TypeError: object of type 'NoneType' has no len()
 40%|███▉      | 68/172 [01:46<01:21,  1.27it/s]INFO:__main__:Requesting https://godoc.org/github.com/etcd-io/etcd/embed
INFO:__main__:Getting metadata for https://godoc.org/github.com/etcd-io/etcd/embed
 40%|████      | 69/172 [01:47<01:01,  1.67it/s]INFO:__main__:Requesting https://github.com/lxc/lxd/blob/master/doc/database.md
INFO:__main__:Getting metadata for https://github.com/lxc/lxd/blob/master/doc/database.md
 41%|████      | 70/172 [01:48<01:29,  1.14it/s]INFO:__main__:Requesting https://github.com/CanonicalLtd/dqlite
INFO:__main__:Getting metadata for https://github.com/CanonicalLtd/dqlite
 41%|████▏     | 71/172 [01:49<01:31,  1.10it/s]INFO:__main__:Requesting https://medium.com/@cfatechblog/bare-metal-k8s-clustering-at-chick-fil-a-scale-7b0607bd3541
INFO:__main__:Getting metadata for https://medium.com/@cfatechblog/bare-metal-k8s-clustering-at-chick-fil-a-scale-7b0607bd3541
 42%|████▏     | 72/172 [01:50<01:18,  1.27it/s]INFO:__main__:Requesting https://thenewstack.io/rancher-takes-kubernetes-management-to-china/
INFO:__main__:Getting metadata for https://thenewstack.io/rancher-takes-kubernetes-management-to-china/
 42%|████▏     | 73/172 [01:50<01:06,  1.49it/s]INFO:__main__:Requesting https://blog.hasura.io/draft-vs-gitkube-vs-helm-vs-ksonnet-vs-metaparticle-vs-skaffold-f5aa9561f948/
INFO:__main__:Getting metadata for https://blog.hasura.io/draft-vs-gitkube-vs-helm-vs-ksonnet-vs-metaparticle-vs-skaffold-f5aa9561f948/
 43%|████▎     | 74/172 [01:52<01:31,  1.07it/s]INFO:__main__:Requesting https://kubernetes.io/blog/2018/05/01/developing-on-kubernetes/
INFO:__main__:Getting metadata for https://kubernetes.io/blog/2018/05/01/developing-on-kubernetes/
 44%|████▎     | 75/172 [01:53<01:50,  1.14s/it]INFO:__main__:Requesting https://electronics.stackexchange.com/questions/32200/why-is-spi-flash-memory-so-limited-in-max-size-and-cost-way-more-per-mb-than
INFO:__main__:Getting metadata for https://electronics.stackexchange.com/questions/32200/why-is-spi-flash-memory-so-limited-in-max-size-and-cost-way-more-per-mb-than
 44%|████▍     | 76/172 [01:54<01:28,  1.08it/s]INFO:__main__:Requesting https://github.com/rancher/k3s#flannel
INFO:__main__:Getting metadata for https://github.com/rancher/k3s#flannel
 45%|████▍     | 77/172 [01:55<01:48,  1.14s/it]INFO:__main__:Requesting https://medium.com/@kvaps/run-kubernetes-in-lxc-container-f04aa94b6c9c
INFO:__main__:Getting metadata for https://medium.com/@kvaps/run-kubernetes-in-lxc-container-f04aa94b6c9c
 45%|████▌     | 78/172 [01:56<01:30,  1.04it/s]INFO:__main__:Requesting https://colab.research.google.com/github/JuliaTPU/XLA.jl/blob/master/examples/3_LSTM_DistributedTraining.ipynb
INFO:__main__:Getting metadata for https://colab.research.google.com/github/JuliaTPU/XLA.jl/blob/master/examples/3_LSTM_DistributedTraining.ipynb
ERROR:__main__:Could not get metadata for https://colab.research.google.com/github/JuliaTPU/XLA.jl/blob/master/examples/3_LSTM_DistributedTraining.ipynb
Traceback (most recent call last):
  File "../_scripts/crawler/crawler.py", line 94, in _get_site_title_and_description
    description = description[:450] + '...' if len(description) > 450 else description
TypeError: object of type 'NoneType' has no len()
 46%|████▌     | 79/172 [01:56<01:08,  1.36it/s]INFO:__main__:Requesting https://www.goodnewsnetwork.org/nasa-says-earth-is-greener-than-ever-thanks-to-china-and-india/
INFO:__main__:Getting metadata for https://www.goodnewsnetwork.org/nasa-says-earth-is-greener-than-ever-thanks-to-china-and-india/
 47%|████▋     | 80/172 [01:57<01:25,  1.07it/s]INFO:__main__:Requesting http://coyoteblog.com/coyote_blog/tag/global-warming
 47%|████▋     | 81/172 [01:58<01:06,  1.37it/s]INFO:__main__:Requesting https://en.wikipedia.org/wiki/Sealioning
INFO:__main__:Getting metadata for https://en.wikipedia.org/wiki/Sealioning
 48%|████▊     | 82/172 [01:58<01:02,  1.43it/s]INFO:__main__:Requesting https://www.scientificamerican.com/article/ask-the-experts-does-rising-co2-benefit-plants1/
INFO:__main__:Getting metadata for https://www.scientificamerican.com/article/ask-the-experts-does-rising-co2-benefit-plants1/
 48%|████▊     | 83/172 [01:59<01:02,  1.41it/s]INFO:__main__:Requesting https://m.phys.org/news/2018-07-electrochemically-produced-ammonia-revolutionize-food-production.html
INFO:__main__:Getting metadata for https://m.phys.org/news/2018-07-electrochemically-produced-ammonia-revolutionize-food-production.html
 49%|████▉     | 84/172 [02:00<01:01,  1.43it/s]INFO:__main__:Requesting https://www.politico.com/agenda/story/2017/09/13/food-nutrients-carbon-dioxide-000511
INFO:__main__:Getting metadata for https://www.politico.com/agenda/story/2017/09/13/food-nutrients-carbon-dioxide-000511
 49%|████▉     | 85/172 [02:00<01:02,  1.40it/s]INFO:__main__:Requesting https://www.nasa.gov/sites/default/files/thumbnails/image/global_tamo_2017_full.png
INFO:__main__:Getting metadata for https://www.nasa.gov/sites/default/files/thumbnails/image/global_tamo_2017_full.png
ERROR:__main__:Could not get metadata for https://www.nasa.gov/sites/default/files/thumbnails/image/global_tamo_2017_full.png
Traceback (most recent call last):
  File "../_scripts/crawler/crawler.py", line 94, in _get_site_title_and_description
    description = description[:450] + '...' if len(description) > 450 else description
TypeError: object of type 'NoneType' has no len()
 50%|█████     | 86/172 [02:42<18:24, 12.84s/it]INFO:__main__:Requesting https://www.nature.com/articles/s41893-019-0220-7
INFO:__main__:Getting metadata for https://www.nature.com/articles/s41893-019-0220-7
 51%|█████     | 87/172 [02:45<14:02,  9.91s/it]INFO:__main__:Requesting https://www.sciencedirect.com/science/article/pii/S1389934118302594
INFO:__main__:Getting metadata for https://www.sciencedirect.com/science/article/pii/S1389934118302594
 51%|█████     | 88/172 [02:45<09:55,  7.09s/it]INFO:__main__:Requesting https://cgspace.cgiar.org/handle/10568/89405
INFO:__main__:Getting metadata for https://cgspace.cgiar.org/handle/10568/89405
ERROR:__main__:Could not get metadata for https://cgspace.cgiar.org/handle/10568/89405
Traceback (most recent call last):
  File "../_scripts/crawler/crawler.py", line 94, in _get_site_title_and_description
    description = description[:450] + '...' if len(description) > 450 else description
TypeError: object of type 'NoneType' has no len()
 52%|█████▏    | 89/172 [03:06<15:23, 11.13s/it]INFO:__main__:Requesting https://en.wikipedia.org/wiki/Moderate_Resolution_Imaging_Spectroradiometer#Applications
INFO:__main__:Getting metadata for https://en.wikipedia.org/wiki/Moderate_Resolution_Imaging_Spectroradiometer#Applications
 52%|█████▏    | 90/172 [03:07<11:04,  8.11s/it]INFO:__main__:Requesting https://www.youtube.com/watch?v=gdfWFDcXut4
INFO:__main__:Getting metadata for https://www.youtube.com/watch?v=gdfWFDcXut4
 53%|█████▎    | 91/172 [03:08<08:01,  5.94s/it]INFO:__main__:Requesting https://www.pnas.org/content/113/21/5768
INFO:__main__:Getting metadata for https://www.pnas.org/content/113/21/5768
 53%|█████▎    | 92/172 [03:11<06:56,  5.21s/it]INFO:__main__:Requesting https://earthscience.stackexchange.com/questions/2639/how-many-trees-would-i-have-to-plant-to-solve-global-warming
INFO:__main__:Getting metadata for https://earthscience.stackexchange.com/questions/2639/how-many-trees-would-i-have-to-plant-to-solve-global-warming
 54%|█████▍    | 93/172 [03:12<05:03,  3.85s/it]INFO:__main__:Requesting https://www.youtube.com/watch?v=yI9wMtTvWps
INFO:__main__:Getting metadata for https://www.youtube.com/watch?v=yI9wMtTvWps
 55%|█████▍    | 94/172 [03:13<03:49,  2.95s/it]INFO:__main__:Requesting https://www.youtube.com/watch?v=vpTHi7O66pI
INFO:__main__:Getting metadata for https://www.youtube.com/watch?v=vpTHi7O66pI
 55%|█████▌    | 95/172 [03:14<03:00,  2.34s/it]INFO:__main__:Requesting https://en.m.wikipedia.org/wiki/Dry_lake
INFO:__main__:Getting metadata for https://en.m.wikipedia.org/wiki/Dry_lake
 56%|█████▌    | 96/172 [03:14<02:22,  1.88s/it]INFO:__main__:Requesting https://en.m.wikipedia.org/wiki/Soil_salinity
INFO:__main__:Getting metadata for https://en.m.wikipedia.org/wiki/Soil_salinity
 56%|█████▋    | 97/172 [03:15<01:56,  1.55s/it]INFO:__main__:Requesting https://en.wikipedia.org/wiki/List_of_countries_by_electricity_production_from_renewable_sources
INFO:__main__:Getting metadata for https://en.wikipedia.org/wiki/List_of_countries_by_electricity_production_from_renewable_sources
 57%|█████▋    | 98/172 [03:18<02:27,  1.99s/it]INFO:__main__:Requesting https://www.youtube.com/watch?v=D5bEwcJ8eCI
INFO:__main__:Getting metadata for https://www.youtube.com/watch?v=D5bEwcJ8eCI
 58%|█████▊    | 99/172 [03:19<02:01,  1.66s/it]INFO:__main__:Requesting https://www.npr.org/sections/money/2013/09/02/216878935/ecuador-to-world-pay-up-to-save-the-rainforest-world-to-ecuador-meh
INFO:__main__:Getting metadata for https://www.npr.org/sections/money/2013/09/02/216878935/ecuador-to-world-pay-up-to-save-the-rainforest-world-to-ecuador-meh
 58%|█████▊    | 100/172 [03:20<01:38,  1.36s/it]INFO:__main__:Requesting https://www.nytimes.com/2018/07/30/science/climate-change-plants-global-greening.html
INFO:__main__:Getting metadata for https://www.nytimes.com/2018/07/30/science/climate-change-plants-global-greening.html
 59%|█████▊    | 101/172 [03:21<01:27,  1.23s/it]INFO:__main__:Requesting https://worldwideweb.cern.ch/
INFO:__main__:Getting metadata for https://worldwideweb.cern.ch
 59%|█████▉    | 102/172 [03:22<01:26,  1.24s/it]INFO:__main__:Requesting https://imgur.com/a/KWl3iUp
INFO:__main__:Getting metadata for https://imgur.com/a/KWl3iUp
ERROR:__main__:Could not get metadata for https://imgur.com/a/KWl3iUp
Traceback (most recent call last):
  File "../_scripts/crawler/crawler.py", line 94, in _get_site_title_and_description
    description = description[:450] + '...' if len(description) > 450 else description
TypeError: object of type 'NoneType' has no len()
 60%|█████▉    | 103/172 [03:23<01:17,  1.12s/it]INFO:__main__:Requesting https://worldwideweb.cern.ch/images/wow.jpg
INFO:__main__:Getting metadata for https://worldwideweb.cern.ch/images/wow.jpg
ERROR:__main__:Could not get metadata for https://worldwideweb.cern.ch/images/wow.jpg
Traceback (most recent call last):
  File "../_scripts/crawler/crawler.py", line 94, in _get_site_title_and_description
    description = description[:450] + '...' if len(description) > 450 else description
TypeError: object of type 'NoneType' has no len()
 60%|██████    | 104/172 [03:30<03:15,  2.87s/it]INFO:__main__:Requesting https://adactio.com
INFO:__main__:Getting metadata for https://adactio.com
 61%|██████    | 105/172 [03:30<02:25,  2.17s/it]INFO:__main__:Requesting https://worldwideweb.cern.ch/colophon/
INFO:__main__:Getting metadata for https://worldwideweb.cern.ch/colophon/
 62%|██████▏   | 106/172 [03:31<02:00,  1.82s/it]INFO:__main__:Requesting https://github.com/djrrb/CERN-www-fonts/blob/master/README.md
 62%|██████▏   | 107/172 [03:32<01:27,  1.34s/it]INFO:__main__:Requesting http://"
ERROR:__main__:Could not reach http://"
Traceback (most recent call last):
  File "/home/travis/virtualenv/python3.6.3/lib/python3.6/site-packages/urllib3/connection.py", line 159, in _new_conn
    (self._dns_host, self.port), self.timeout, **extra_kw)
  File "/home/travis/virtualenv/python3.6.3/lib/python3.6/site-packages/urllib3/util/connection.py", line 57, in create_connection
    for res in socket.getaddrinfo(host, port, family, socket.SOCK_STREAM):
  File "/opt/python/3.6.3/lib/python3.6/socket.py", line 745, in getaddrinfo
    for res in _socket.getaddrinfo(host, port, family, type, proto, flags):
socket.gaierror: [Errno -2] Name or service not known

During handling of the above exception, another exception occurred:

Traceback (most recent call last):
  File "/home/travis/virtualenv/python3.6.3/lib/python3.6/site-packages/urllib3/connectionpool.py", line 600, in urlopen
    chunked=chunked)
  File "/home/travis/virtualenv/python3.6.3/lib/python3.6/site-packages/urllib3/connectionpool.py", line 354, in _make_request
    conn.request(method, url, **httplib_request_kw)
  File "/opt/python/3.6.3/lib/python3.6/http/client.py", line 1239, in request
    self._send_request(method, url, body, headers, encode_chunked)
  File "/opt/python/3.6.3/lib/python3.6/http/client.py", line 1285, in _send_request
    self.endheaders(body, encode_chunked=encode_chunked)
  File "/opt/python/3.6.3/lib/python3.6/http/client.py", line 1234, in endheaders
    self._send_output(message_body, encode_chunked=encode_chunked)
  File "/opt/python/3.6.3/lib/python3.6/http/client.py", line 1026, in _send_output
    self.send(msg)
  File "/opt/python/3.6.3/lib/python3.6/http/client.py", line 964, in send
    self.connect()
  File "/home/travis/virtualenv/python3.6.3/lib/python3.6/site-packages/urllib3/connection.py", line 181, in connect
    conn = self._new_conn()
  File "/home/travis/virtualenv/python3.6.3/lib/python3.6/site-packages/urllib3/connection.py", line 168, in _new_conn
    self, "Failed to establish a new connection: %s" % e)
urllib3.exceptions.NewConnectionError: <urllib3.connection.HTTPConnection object at 0x7ff6b20b9e48>: Failed to establish a new connection: [Errno -2] Name or service not known

During handling of the above exception, another exception occurred:

Traceback (most recent call last):
  File "/home/travis/virtualenv/python3.6.3/lib/python3.6/site-packages/requests/adapters.py", line 449, in send
    timeout=timeout
  File "/home/travis/virtualenv/python3.6.3/lib/python3.6/site-packages/urllib3/connectionpool.py", line 638, in urlopen
    _stacktrace=sys.exc_info()[2])
  File "/home/travis/virtualenv/python3.6.3/lib/python3.6/site-packages/urllib3/util/retry.py", line 398, in increment
    raise MaxRetryError(_pool, url, error or ResponseError(cause))
urllib3.exceptions.MaxRetryError: HTTPConnectionPool(host='%22', port=80): Max retries exceeded with url: / (Caused by NewConnectionError('<urllib3.connection.HTTPConnection object at 0x7ff6b20b9e48>: Failed to establish a new connection: [Errno -2] Name or service not known',))

During handling of the above exception, another exception occurred:

Traceback (most recent call last):
  File "../_scripts/crawler/crawler.py", line 210, in metafy_url
    response = requests.get(url, timeout=6, headers={'User-Agent': 'Mozilla/5.0'})
  File "/home/travis/virtualenv/python3.6.3/lib/python3.6/site-packages/requests/api.py", line 75, in get
    return request('get', url, params=params, **kwargs)
  File "/home/travis/virtualenv/python3.6.3/lib/python3.6/site-packages/requests/api.py", line 60, in request
    return session.request(method=method, url=url, **kwargs)
  File "/home/travis/virtualenv/python3.6.3/lib/python3.6/site-packages/requests/sessions.py", line 533, in request
    resp = self.send(prep, **send_kwargs)
  File "/home/travis/virtualenv/python3.6.3/lib/python3.6/site-packages/requests/sessions.py", line 646, in send
    r = adapter.send(request, **kwargs)
  File "/home/travis/virtualenv/python3.6.3/lib/python3.6/site-packages/requests/adapters.py", line 516, in send
    raise ConnectionError(e, request=request)
requests.exceptions.ConnectionError: HTTPConnectionPool(host='%22', port=80): Max retries exceeded with url: / (Caused by NewConnectionError('<urllib3.connection.HTTPConnection object at 0x7ff6b20b9e48>: Failed to establish a new connection: [Errno -2] Name or service not known',))
INFO:__main__:Requesting https://www.confluent.io/blog/noise-mapping-ksql-raspberry-pi-software-defined-radio
INFO:__main__:Getting metadata for https://www.confluent.io/blog/noise-mapping-ksql-raspberry-pi-software-defined-radio
 63%|██████▎   | 109/172 [03:32<01:00,  1.04it/s]INFO:__main__:Requesting https://webtrak.emsbk.com/lax4
INFO:__main__:Getting metadata for https://webtrak.emsbk.com/lax4
 64%|██████▍   | 110/172 [03:33<01:09,  1.12s/it]INFO:__main__:Requesting https://www.eetimes.com/document.asp?doc_id=1334373
ERROR:__main__:Could not reach https://www.eetimes.com/document.asp?doc_id=1334373
Traceback (most recent call last):
  File "/home/travis/virtualenv/python3.6.3/lib/python3.6/site-packages/urllib3/connectionpool.py", line 384, in _make_request
    six.raise_from(e, None)
  File "<string>", line 2, in raise_from
  File "/home/travis/virtualenv/python3.6.3/lib/python3.6/site-packages/urllib3/connectionpool.py", line 380, in _make_request
    httplib_response = conn.getresponse()
  File "/opt/python/3.6.3/lib/python3.6/http/client.py", line 1331, in getresponse
    response.begin()
  File "/opt/python/3.6.3/lib/python3.6/http/client.py", line 297, in begin
    version, status, reason = self._read_status()
  File "/opt/python/3.6.3/lib/python3.6/http/client.py", line 258, in _read_status
    line = str(self.fp.readline(_MAXLINE + 1), "iso-8859-1")
  File "/opt/python/3.6.3/lib/python3.6/socket.py", line 586, in readinto
    return self._sock.recv_into(b)
  File "/opt/python/3.6.3/lib/python3.6/ssl.py", line 1009, in recv_into
    return self.read(nbytes, buffer)
  File "/opt/python/3.6.3/lib/python3.6/ssl.py", line 871, in read
    return self._sslobj.read(len, buffer)
  File "/opt/python/3.6.3/lib/python3.6/ssl.py", line 631, in read
    v = self._sslobj.read(len, buffer)
socket.timeout: The read operation timed out

During handling of the above exception, another exception occurred:

Traceback (most recent call last):
  File "/home/travis/virtualenv/python3.6.3/lib/python3.6/site-packages/requests/adapters.py", line 449, in send
    timeout=timeout
  File "/home/travis/virtualenv/python3.6.3/lib/python3.6/site-packages/urllib3/connectionpool.py", line 638, in urlopen
    _stacktrace=sys.exc_info()[2])
  File "/home/travis/virtualenv/python3.6.3/lib/python3.6/site-packages/urllib3/util/retry.py", line 367, in increment
    raise six.reraise(type(error), error, _stacktrace)
  File "/home/travis/virtualenv/python3.6.3/lib/python3.6/site-packages/urllib3/packages/six.py", line 686, in reraise
    raise value
  File "/home/travis/virtualenv/python3.6.3/lib/python3.6/site-packages/urllib3/connectionpool.py", line 600, in urlopen
    chunked=chunked)
  File "/home/travis/virtualenv/python3.6.3/lib/python3.6/site-packages/urllib3/connectionpool.py", line 386, in _make_request
    self._raise_timeout(err=e, url=url, timeout_value=read_timeout)
  File "/home/travis/virtualenv/python3.6.3/lib/python3.6/site-packages/urllib3/connectionpool.py", line 306, in _raise_timeout
    raise ReadTimeoutError(self, url, "Read timed out. (read timeout=%s)" % timeout_value)
urllib3.exceptions.ReadTimeoutError: HTTPSConnectionPool(host='www.eetimes.com', port=443): Read timed out. (read timeout=6)

During handling of the above exception, another exception occurred:

Traceback (most recent call last):
  File "../_scripts/crawler/crawler.py", line 210, in metafy_url
    response = requests.get(url, timeout=6, headers={'User-Agent': 'Mozilla/5.0'})
  File "/home/travis/virtualenv/python3.6.3/lib/python3.6/site-packages/requests/api.py", line 75, in get
    return request('get', url, params=params, **kwargs)
  File "/home/travis/virtualenv/python3.6.3/lib/python3.6/site-packages/requests/api.py", line 60, in request
    return session.request(method=method, url=url, **kwargs)
  File "/home/travis/virtualenv/python3.6.3/lib/python3.6/site-packages/requests/sessions.py", line 533, in request
    resp = self.send(prep, **send_kwargs)
  File "/home/travis/virtualenv/python3.6.3/lib/python3.6/site-packages/requests/sessions.py", line 646, in send
    r = adapter.send(request, **kwargs)
  File "/home/travis/virtualenv/python3.6.3/lib/python3.6/site-packages/requests/adapters.py", line 529, in send
    raise ReadTimeout(e, request=request)
requests.exceptions.ReadTimeout: HTTPSConnectionPool(host='www.eetimes.com', port=443): Read timed out. (read timeout=6)
 65%|██████▍   | 111/172 [03:39<02:41,  2.65s/it]INFO:__main__:Requesting http://www.p01.org/defender_of_the_favicon/
INFO:__main__:Getting metadata for http://www.p01.org/defender_of_the_favicon/
 65%|██████▌   | 112/172 [03:41<02:20,  2.34s/it]INFO:__main__:Requesting https://github.com/cablespaghetti/kubeadm-aws
INFO:__main__:Getting metadata for https://github.com/cablespaghetti/kubeadm-aws
 66%|██████▌   | 113/172 [03:42<01:54,  1.94s/it]INFO:__main__:Requesting https://github.com/hobby-kube/guide
INFO:__main__:Getting metadata for https://github.com/hobby-kube/guide
 66%|██████▋   | 114/172 [03:43<01:37,  1.69s/it]INFO:__main__:Requesting https://www.ovh.co.uk/kubernetes/
INFO:__main__:Getting metadata for https://www.ovh.co.uk/kubernetes/
 67%|██████▋   | 115/172 [03:44<01:25,  1.51s/it]INFO:__main__:Requesting https://www.hetzner.com/rechtliches/agb
INFO:__main__:Getting metadata for https://www.hetzner.com/rechtliches/agb
 67%|██████▋   | 116/172 [03:49<02:15,  2.41s/it]INFO:__main__:Requesting https://www.radishlogic.com/kubernetes/running-minikube-in-aws-ec2-ubuntu/
INFO:__main__:Getting metadata for https://www.radishlogic.com/kubernetes/running-minikube-in-aws-ec2-ubuntu/
 68%|██████▊   | 117/172 [03:49<01:41,  1.85s/it]INFO:__main__:Requesting https://github.com/GoogleContainerTools/kubehost
INFO:__main__:Getting metadata for https://github.com/GoogleContainerTools/kubehost
 69%|██████▊   | 118/172 [03:51<01:38,  1.83s/it]INFO:__main__:Requesting https://github.com/kubernetes/kops
INFO:__main__:Getting metadata for https://github.com/kubernetes/kops
 69%|██████▉   | 119/172 [03:52<01:25,  1.61s/it]INFO:__main__:Requesting https://www.nature.com/articles/d41586-019-00577-0
INFO:__main__:Getting metadata for https://www.nature.com/articles/d41586-019-00577-0
 70%|██████▉   | 120/172 [03:54<01:32,  1.78s/it]INFO:__main__:Requesting https://en.wikipedia.org/wiki/Semi-empirical_mass_formula
INFO:__main__:Getting metadata for https://en.wikipedia.org/wiki/Semi-empirical_mass_formula
 70%|███████   | 121/172 [03:56<01:29,  1.75s/it]INFO:__main__:Requesting https://www.nytimes.com/2019/02/26/dining/homemade-yogurt-starter-south-asia.html
INFO:__main__:Getting metadata for https://www.nytimes.com/2019/02/26/dining/homemade-yogurt-starter-south-asia.html
 71%|███████   | 122/172 [03:56<01:04,  1.30s/it]INFO:__main__:Requesting http://blog.lareviewofbooks.org/essays/self-publishing-pleased-brief-glimpse-life-small-town-bookseller-writer/
INFO:__main__:Getting metadata for http://blog.lareviewofbooks.org/essays/self-publishing-pleased-brief-glimpse-life-small-town-bookseller-writer/
 72%|███████▏  | 123/172 [03:58<01:14,  1.51s/it]INFO:__main__:Requesting https://www.theguardian.com/cities/2019/feb/21/philadelphia-covanta-incinerator-recyclables-china-ban-imports
INFO:__main__:Getting metadata for https://www.theguardian.com/cities/2019/feb/21/philadelphia-covanta-incinerator-recyclables-china-ban-imports
 72%|███████▏  | 124/172 [03:59<00:55,  1.16s/it]INFO:__main__:Requesting https://www.opb.org/news/article/oregon-craft-beer-refillable-bottles/
INFO:__main__:Getting metadata for https://www.opb.org/news/article/oregon-craft-beer-refillable-bottles/
 73%|███████▎  | 125/172 [04:00<00:52,  1.12s/it]INFO:__main__:Requesting https://cleantechnica.com/2019/02/19/loop-to-launch-zero-waste-delivery-service-in-new-york-this-spring/
INFO:__main__:Getting metadata for https://cleantechnica.com/2019/02/19/loop-to-launch-zero-waste-delivery-service-in-new-york-this-spring/
 73%|███████▎  | 126/172 [04:00<00:38,  1.18it/s]INFO:__main__:Requesting http://knowledge.wharton.upenn.edu/article/reusable-packaging-loop/
INFO:__main__:Getting metadata for http://knowledge.wharton.upenn.edu/article/reusable-packaging-loop/
 74%|███████▍  | 127/172 [04:01<00:41,  1.09it/s]INFO:__main__:Requesting https://www.fastcompany.com/90296956/a-coalition-of-giant-brands-is-about-to-change-how-we-shop-forever-with-a-new-zero-waste-platform
INFO:__main__:Getting metadata for https://www.fastcompany.com/90296956/a-coalition-of-giant-brands-is-about-to-change-how-we-shop-forever-with-a-new-zero-waste-platform
 74%|███████▍  | 128/172 [04:01<00:31,  1.38it/s]INFO:__main__:Requesting https://www.fastcompany.com/90239092/this-reusable-beer-bottle-could-change-the-way-america-drinks
INFO:__main__:Getting metadata for https://www.fastcompany.com/90239092/this-reusable-beer-bottle-could-change-the-way-america-drinks
 75%|███████▌  | 129/172 [04:02<00:26,  1.60it/s]INFO:__main__:Requesting https://www.imdb.com/title/tt0771119/
INFO:__main__:Getting metadata for https://www.imdb.com/title/tt0771119/
 76%|███████▌  | 130/172 [04:03<00:31,  1.35it/s]INFO:__main__:Requesting https://www.youtube.com/watch?v=koqNm_TgOZk
INFO:__main__:Getting metadata for https://www.youtube.com/watch?v=koqNm_TgOZk
 76%|███████▌  | 131/172 [04:03<00:31,  1.29it/s]INFO:__main__:Requesting https://news.nationalgeographic.com/2018/06/china-plastic-recycling-ban-solutions-science-environment/
INFO:__main__:Getting metadata for https://news.nationalgeographic.com/2018/06/china-plastic-recycling-ban-solutions-science-environment/
 77%|███████▋  | 132/172 [04:04<00:28,  1.39it/s]INFO:__main__:Requesting https://www.horizon.com/faqs?f%5B5%5D=field_faq_category%3A98
INFO:__main__:Getting metadata for https://www.horizon.com/faqs?f%5B5%5D=field_faq_category%3A98
 77%|███████▋  | 133/172 [04:09<01:17,  1.99s/it]INFO:__main__:Requesting https://static.businessinsider.com/image/4b05d2300000000000dadafc/image.jpg
INFO:__main__:Getting metadata for https://static.businessinsider.com/image/4b05d2300000000000dadafc/image.jpg
ERROR:__main__:Could not get metadata for https://static.businessinsider.com/image/4b05d2300000000000dadafc/image.jpg
Traceback (most recent call last):
  File "../_scripts/crawler/crawler.py", line 94, in _get_site_title_and_description
    description = description[:450] + '...' if len(description) > 450 else description
TypeError: object of type 'NoneType' has no len()
 78%|███████▊  | 134/172 [04:14<01:51,  2.92s/it]INFO:__main__:Requesting https://www.econtalk.org/michael-munger-on-sharing-transaction-costs-and-tomorrow-3-0/
INFO:__main__:Getting metadata for https://www.econtalk.org/michael-munger-on-sharing-transaction-costs-and-tomorrow-3-0/
 78%|███████▊  | 135/172 [04:17<01:45,  2.84s/it]INFO:__main__:Requesting https://en.wikipedia.org/wiki/Plasma_gasification_commercialization
INFO:__main__:Getting metadata for https://en.wikipedia.org/wiki/Plasma_gasification_commercialization
 79%|███████▉  | 136/172 [04:18<01:22,  2.29s/it]INFO:__main__:Requesting https://www.fairfaxcounty.gov/publicworks/recycling-trash/energy-resource-recovery-facility
INFO:__main__:Getting metadata for https://www.fairfaxcounty.gov/publicworks/recycling-trash/energy-resource-recovery-facility
 80%|███████▉  | 137/172 [04:21<01:26,  2.48s/it]INFO:__main__:Requesting http://www.pinellascounty.org/solidwaste/wte.htm
INFO:__main__:Getting metadata for http://www.pinellascounty.org/solidwaste/wte.htm
 80%|████████  | 138/172 [04:22<01:11,  2.09s/it]INFO:__main__:Requesting https://en.wikipedia.org/wiki/Dickerson_Generating_Station#Montgomery_County_Resource_Recovery_Facility
INFO:__main__:Getting metadata for https://en.wikipedia.org/wiki/Dickerson_Generating_Station#Montgomery_County_Resource_Recovery_Facility
 81%|████████  | 139/172 [04:23<00:55,  1.70s/it]INFO:__main__:Requesting http://www.tetrapakrecycling.co.uk/protect-whats-good-environment-recyclable.asp
INFO:__main__:Getting metadata for http://www.tetrapakrecycling.co.uk/protect-whats-good-environment-recyclable.asp
 81%|████████▏ | 140/172 [04:26<01:11,  2.24s/it]INFO:__main__:Requesting http://renewlogy.com/renew-energy/
INFO:__main__:Getting metadata for http://renewlogy.com/renew-energy/
 82%|████████▏ | 141/172 [04:33<01:50,  3.56s/it]INFO:__main__:Requesting https://en.m.wikipedia.org/wiki/Black_Triangle_(region)
INFO:__main__:Getting metadata for https://en.m.wikipedia.org/wiki/Black_Triangle_(region)
 83%|████████▎ | 142/172 [04:34<01:21,  2.71s/it]INFO:__main__:Requesting https://en.wikipedia.org/wiki/A_Big_Piece_of_Garbage
INFO:__main__:Getting metadata for https://en.wikipedia.org/wiki/A_Big_Piece_of_Garbage
 83%|████████▎ | 143/172 [04:34<01:00,  2.10s/it]INFO:__main__:Requesting https://www.washingtonpost.com/news/wonk/wp/2013/05/09/chinas-crackdown-on-trash-could-make-it-harder-for-u-s-cities-to-recycle/
ERROR:__main__:Could not reach https://www.washingtonpost.com/news/wonk/wp/2013/05/09/chinas-crackdown-on-trash-could-make-it-harder-for-u-s-cities-to-recycle/
Traceback (most recent call last):
  File "/home/travis/virtualenv/python3.6.3/lib/python3.6/site-packages/urllib3/connectionpool.py", line 384, in _make_request
    six.raise_from(e, None)
  File "<string>", line 2, in raise_from
  File "/home/travis/virtualenv/python3.6.3/lib/python3.6/site-packages/urllib3/connectionpool.py", line 380, in _make_request
    httplib_response = conn.getresponse()
  File "/opt/python/3.6.3/lib/python3.6/http/client.py", line 1331, in getresponse
    response.begin()
  File "/opt/python/3.6.3/lib/python3.6/http/client.py", line 297, in begin
    version, status, reason = self._read_status()
  File "/opt/python/3.6.3/lib/python3.6/http/client.py", line 258, in _read_status
    line = str(self.fp.readline(_MAXLINE + 1), "iso-8859-1")
  File "/opt/python/3.6.3/lib/python3.6/socket.py", line 586, in readinto
    return self._sock.recv_into(b)
  File "/opt/python/3.6.3/lib/python3.6/ssl.py", line 1009, in recv_into
    return self.read(nbytes, buffer)
  File "/opt/python/3.6.3/lib/python3.6/ssl.py", line 871, in read
    return self._sslobj.read(len, buffer)
  File "/opt/python/3.6.3/lib/python3.6/ssl.py", line 631, in read
    v = self._sslobj.read(len, buffer)
socket.timeout: The read operation timed out

During handling of the above exception, another exception occurred:

Traceback (most recent call last):
  File "/home/travis/virtualenv/python3.6.3/lib/python3.6/site-packages/requests/adapters.py", line 449, in send
    timeout=timeout
  File "/home/travis/virtualenv/python3.6.3/lib/python3.6/site-packages/urllib3/connectionpool.py", line 638, in urlopen
    _stacktrace=sys.exc_info()[2])
  File "/home/travis/virtualenv/python3.6.3/lib/python3.6/site-packages/urllib3/util/retry.py", line 367, in increment
    raise six.reraise(type(error), error, _stacktrace)
  File "/home/travis/virtualenv/python3.6.3/lib/python3.6/site-packages/urllib3/packages/six.py", line 686, in reraise
    raise value
  File "/home/travis/virtualenv/python3.6.3/lib/python3.6/site-packages/urllib3/connectionpool.py", line 600, in urlopen
    chunked=chunked)
  File "/home/travis/virtualenv/python3.6.3/lib/python3.6/site-packages/urllib3/connectionpool.py", line 386, in _make_request
    self._raise_timeout(err=e, url=url, timeout_value=read_timeout)
  File "/home/travis/virtualenv/python3.6.3/lib/python3.6/site-packages/urllib3/connectionpool.py", line 306, in _raise_timeout
    raise ReadTimeoutError(self, url, "Read timed out. (read timeout=%s)" % timeout_value)
urllib3.exceptions.ReadTimeoutError: HTTPSConnectionPool(host='www.washingtonpost.com', port=443): Read timed out. (read timeout=6)

During handling of the above exception, another exception occurred:

Traceback (most recent call last):
  File "../_scripts/crawler/crawler.py", line 210, in metafy_url
    response = requests.get(url, timeout=6, headers={'User-Agent': 'Mozilla/5.0'})
  File "/home/travis/virtualenv/python3.6.3/lib/python3.6/site-packages/requests/api.py", line 75, in get
    return request('get', url, params=params, **kwargs)
  File "/home/travis/virtualenv/python3.6.3/lib/python3.6/site-packages/requests/api.py", line 60, in request
    return session.request(method=method, url=url, **kwargs)
  File "/home/travis/virtualenv/python3.6.3/lib/python3.6/site-packages/requests/sessions.py", line 533, in request
    resp = self.send(prep, **send_kwargs)
  File "/home/travis/virtualenv/python3.6.3/lib/python3.6/site-packages/requests/sessions.py", line 646, in send
    r = adapter.send(request, **kwargs)
  File "/home/travis/virtualenv/python3.6.3/lib/python3.6/site-packages/requests/adapters.py", line 529, in send
    raise ReadTimeout(e, request=request)
requests.exceptions.ReadTimeout: HTTPSConnectionPool(host='www.washingtonpost.com', port=443): Read timed out. (read timeout=6)
 84%|████████▎ | 144/172 [04:40<01:32,  3.29s/it]INFO:__main__:Requesting https://sensorstechforum.com/smart-homes-at-risk-to-hackers/
INFO:__main__:Getting metadata for https://sensorstechforum.com/smart-homes-at-risk-to-hackers/
 84%|████████▍ | 145/172 [04:42<01:18,  2.90s/it]INFO:__main__:Requesting https://longform.org/posts/the-mastermind
INFO:__main__:Getting metadata for https://longform.org/posts/the-mastermind
 85%|████████▍ | 146/172 [04:43<00:56,  2.16s/it]INFO:__main__:Requesting https://pvk.ca/Blog/2019/02/25/the-unscalable-thread-pool/
INFO:__main__:Getting metadata for https://pvk.ca/Blog/2019/02/25/the-unscalable-thread-pool/
 85%|████████▌ | 147/172 [04:46<01:00,  2.42s/it]INFO:__main__:Requesting https://cpmaker.com
ERROR:__main__:Could not reach https://cpmaker.com
Traceback (most recent call last):
  File "/home/travis/virtualenv/python3.6.3/lib/python3.6/site-packages/urllib3/connectionpool.py", line 600, in urlopen
    chunked=chunked)
  File "/home/travis/virtualenv/python3.6.3/lib/python3.6/site-packages/urllib3/connectionpool.py", line 343, in _make_request
    self._validate_conn(conn)
  File "/home/travis/virtualenv/python3.6.3/lib/python3.6/site-packages/urllib3/connectionpool.py", line 839, in _validate_conn
    conn.connect()
  File "/home/travis/virtualenv/python3.6.3/lib/python3.6/site-packages/urllib3/connection.py", line 344, in connect
    ssl_context=context)
  File "/home/travis/virtualenv/python3.6.3/lib/python3.6/site-packages/urllib3/util/ssl_.py", line 344, in ssl_wrap_socket
    return context.wrap_socket(sock, server_hostname=server_hostname)
  File "/opt/python/3.6.3/lib/python3.6/ssl.py", line 407, in wrap_socket
    _context=self, _session=session)
  File "/opt/python/3.6.3/lib/python3.6/ssl.py", line 814, in __init__
    self.do_handshake()
  File "/opt/python/3.6.3/lib/python3.6/ssl.py", line 1068, in do_handshake
    self._sslobj.do_handshake()
  File "/opt/python/3.6.3/lib/python3.6/ssl.py", line 689, in do_handshake
    self._sslobj.do_handshake()
ConnectionResetError: [Errno 104] Connection reset by peer

During handling of the above exception, another exception occurred:

Traceback (most recent call last):
  File "/home/travis/virtualenv/python3.6.3/lib/python3.6/site-packages/requests/adapters.py", line 449, in send
    timeout=timeout
  File "/home/travis/virtualenv/python3.6.3/lib/python3.6/site-packages/urllib3/connectionpool.py", line 638, in urlopen
    _stacktrace=sys.exc_info()[2])
  File "/home/travis/virtualenv/python3.6.3/lib/python3.6/site-packages/urllib3/util/retry.py", line 367, in increment
    raise six.reraise(type(error), error, _stacktrace)
  File "/home/travis/virtualenv/python3.6.3/lib/python3.6/site-packages/urllib3/packages/six.py", line 685, in reraise
    raise value.with_traceback(tb)
  File "/home/travis/virtualenv/python3.6.3/lib/python3.6/site-packages/urllib3/connectionpool.py", line 600, in urlopen
    chunked=chunked)
  File "/home/travis/virtualenv/python3.6.3/lib/python3.6/site-packages/urllib3/connectionpool.py", line 343, in _make_request
    self._validate_conn(conn)
  File "/home/travis/virtualenv/python3.6.3/lib/python3.6/site-packages/urllib3/connectionpool.py", line 839, in _validate_conn
    conn.connect()
  File "/home/travis/virtualenv/python3.6.3/lib/python3.6/site-packages/urllib3/connection.py", line 344, in connect
    ssl_context=context)
  File "/home/travis/virtualenv/python3.6.3/lib/python3.6/site-packages/urllib3/util/ssl_.py", line 344, in ssl_wrap_socket
    return context.wrap_socket(sock, server_hostname=server_hostname)
  File "/opt/python/3.6.3/lib/python3.6/ssl.py", line 407, in wrap_socket
    _context=self, _session=session)
  File "/opt/python/3.6.3/lib/python3.6/ssl.py", line 814, in __init__
    self.do_handshake()
  File "/opt/python/3.6.3/lib/python3.6/ssl.py", line 1068, in do_handshake
    self._sslobj.do_handshake()
  File "/opt/python/3.6.3/lib/python3.6/ssl.py", line 689, in do_handshake
    self._sslobj.do_handshake()
urllib3.exceptions.ProtocolError: ('Connection aborted.', ConnectionResetError(104, 'Connection reset by peer'))

During handling of the above exception, another exception occurred:

Traceback (most recent call last):
  File "../_scripts/crawler/crawler.py", line 210, in metafy_url
    response = requests.get(url, timeout=6, headers={'User-Agent': 'Mozilla/5.0'})
  File "/home/travis/virtualenv/python3.6.3/lib/python3.6/site-packages/requests/api.py", line 75, in get
    return request('get', url, params=params, **kwargs)
  File "/home/travis/virtualenv/python3.6.3/lib/python3.6/site-packages/requests/api.py", line 60, in request
    return session.request(method=method, url=url, **kwargs)
  File "/home/travis/virtualenv/python3.6.3/lib/python3.6/site-packages/requests/sessions.py", line 533, in request
    resp = self.send(prep, **send_kwargs)
  File "/home/travis/virtualenv/python3.6.3/lib/python3.6/site-packages/requests/sessions.py", line 646, in send
    r = adapter.send(request, **kwargs)
  File "/home/travis/virtualenv/python3.6.3/lib/python3.6/site-packages/requests/adapters.py", line 498, in send
    raise ConnectionError(err, request=request)
requests.exceptions.ConnectionError: ('Connection aborted.', ConnectionResetError(104, 'Connection reset by peer'))
 86%|████████▌ | 148/172 [04:46<00:41,  1.73s/it]INFO:__main__:Requesting https://dragan.rocks/articles/18/CUDA-10-in-Clojure
INFO:__main__:Getting metadata for https://dragan.rocks/articles/18/CUDA-10-in-Clojure
 87%|████████▋ | 149/172 [04:47<00:35,  1.55s/it]INFO:__main__:Requesting https://aws.amazon.com/personalize/
INFO:__main__:Getting metadata for https://aws.amazon.com/personalize/
ERROR:__main__:Could not get metadata for https://aws.amazon.com/personalize/
Traceback (most recent call last):
  File "../_scripts/crawler/crawler.py", line 94, in _get_site_title_and_description
    description = description[:450] + '...' if len(description) > 450 else description
TypeError: object of type 'NoneType' has no len()
 87%|████████▋ | 150/172 [04:49<00:35,  1.63s/it]INFO:__main__:Requesting https://www.wired.com/2012/04/netflix-prize-costs/
INFO:__main__:Getting metadata for https://www.wired.com/2012/04/netflix-prize-costs/
 88%|████████▊ | 151/172 [04:49<00:25,  1.21s/it]INFO:__main__:Requesting https://en.wikipedia.org/wiki/Hierarchical_temporal_memory
INFO:__main__:Getting metadata for https://en.wikipedia.org/wiki/Hierarchical_temporal_memory
 88%|████████▊ | 152/172 [04:50<00:22,  1.13s/it]INFO:__main__:Requesting https://en.m.wikipedia.org/wiki/Onavo
INFO:__main__:Getting metadata for https://en.m.wikipedia.org/wiki/Onavo
 89%|████████▉ | 153/172 [04:51<00:21,  1.14s/it]INFO:__main__:Requesting https://www.linkedin.com/in/michaelparis1/
 90%|████████▉ | 154/172 [04:51<00:15,  1.16it/s]INFO:__main__:Requesting https://mobile.twitter.com/patio11/status/982208307057246209
INFO:__main__:Getting metadata for https://mobile.twitter.com/patio11/status/982208307057246209
ERROR:__main__:Could not get metadata for https://mobile.twitter.com/patio11/status/982208307057246209
Traceback (most recent call last):
  File "../_scripts/crawler/crawler.py", line 94, in _get_site_title_and_description
    description = description[:450] + '...' if len(description) > 450 else description
TypeError: object of type 'NoneType' has no len()
 90%|█████████ | 155/172 [04:53<00:19,  1.14s/it]INFO:__main__:Requesting https://threadreaderapp.com/thread/982208307057246209.html
INFO:__main__:Getting metadata for https://threadreaderapp.com/thread/982208307057246209.html
 91%|█████████ | 156/172 [04:53<00:13,  1.15it/s]INFO:__main__:Requesting https://techcrunch.com/2016/11/03/amazons-private-label-brands-are-killing-it-says-new-report/
ERROR:__main__:Could not reach https://techcrunch.com/2016/11/03/amazons-private-label-brands-are-killing-it-says-new-report/
Traceback (most recent call last):
  File "/home/travis/virtualenv/python3.6.3/lib/python3.6/site-packages/urllib3/connectionpool.py", line 600, in urlopen
    chunked=chunked)
  File "/home/travis/virtualenv/python3.6.3/lib/python3.6/site-packages/urllib3/connectionpool.py", line 384, in _make_request
    six.raise_from(e, None)
  File "<string>", line 2, in raise_from
  File "/home/travis/virtualenv/python3.6.3/lib/python3.6/site-packages/urllib3/connectionpool.py", line 380, in _make_request
    httplib_response = conn.getresponse()
  File "/opt/python/3.6.3/lib/python3.6/http/client.py", line 1331, in getresponse
    response.begin()
  File "/opt/python/3.6.3/lib/python3.6/http/client.py", line 297, in begin
    version, status, reason = self._read_status()
  File "/opt/python/3.6.3/lib/python3.6/http/client.py", line 266, in _read_status
    raise RemoteDisconnected("Remote end closed connection without"
http.client.RemoteDisconnected: Remote end closed connection without response

During handling of the above exception, another exception occurred:

Traceback (most recent call last):
  File "/home/travis/virtualenv/python3.6.3/lib/python3.6/site-packages/requests/adapters.py", line 449, in send
    timeout=timeout
  File "/home/travis/virtualenv/python3.6.3/lib/python3.6/site-packages/urllib3/connectionpool.py", line 638, in urlopen
    _stacktrace=sys.exc_info()[2])
  File "/home/travis/virtualenv/python3.6.3/lib/python3.6/site-packages/urllib3/util/retry.py", line 367, in increment
    raise six.reraise(type(error), error, _stacktrace)
  File "/home/travis/virtualenv/python3.6.3/lib/python3.6/site-packages/urllib3/packages/six.py", line 685, in reraise
    raise value.with_traceback(tb)
  File "/home/travis/virtualenv/python3.6.3/lib/python3.6/site-packages/urllib3/connectionpool.py", line 600, in urlopen
    chunked=chunked)
  File "/home/travis/virtualenv/python3.6.3/lib/python3.6/site-packages/urllib3/connectionpool.py", line 384, in _make_request
    six.raise_from(e, None)
  File "<string>", line 2, in raise_from
  File "/home/travis/virtualenv/python3.6.3/lib/python3.6/site-packages/urllib3/connectionpool.py", line 380, in _make_request
    httplib_response = conn.getresponse()
  File "/opt/python/3.6.3/lib/python3.6/http/client.py", line 1331, in getresponse
    response.begin()
  File "/opt/python/3.6.3/lib/python3.6/http/client.py", line 297, in begin
    version, status, reason = self._read_status()
  File "/opt/python/3.6.3/lib/python3.6/http/client.py", line 266, in _read_status
    raise RemoteDisconnected("Remote end closed connection without"
urllib3.exceptions.ProtocolError: ('Connection aborted.', RemoteDisconnected('Remote end closed connection without response',))

During handling of the above exception, another exception occurred:

Traceback (most recent call last):
  File "../_scripts/crawler/crawler.py", line 210, in metafy_url
    response = requests.get(url, timeout=6, headers={'User-Agent': 'Mozilla/5.0'})
  File "/home/travis/virtualenv/python3.6.3/lib/python3.6/site-packages/requests/api.py", line 75, in get
    return request('get', url, params=params, **kwargs)
  File "/home/travis/virtualenv/python3.6.3/lib/python3.6/site-packages/requests/api.py", line 60, in request
    return session.request(method=method, url=url, **kwargs)
  File "/home/travis/virtualenv/python3.6.3/lib/python3.6/site-packages/requests/sessions.py", line 533, in request
    resp = self.send(prep, **send_kwargs)
  File "/home/travis/virtualenv/python3.6.3/lib/python3.6/site-packages/requests/sessions.py", line 646, in send
    r = adapter.send(request, **kwargs)
  File "/home/travis/virtualenv/python3.6.3/lib/python3.6/site-packages/requests/adapters.py", line 498, in send
    raise ConnectionError(err, request=request)
requests.exceptions.ConnectionError: ('Connection aborted.', RemoteDisconnected('Remote end closed connection without response',))
 91%|█████████▏| 157/172 [04:53<00:09,  1.54it/s]INFO:__main__:Requesting https://www.cnbc.com/2014/04/09/big-data-knows-youre-pregnant-and-thats-not-all.html
INFO:__main__:Getting metadata for https://www.cnbc.com/2014/04/09/big-data-knows-youre-pregnant-and-thats-not-all.html
 92%|█████████▏| 158/172 [04:55<00:12,  1.11it/s]INFO:__main__:Requesting https://mubi.com/notebook/posts/interview-with-fritz-lang-beverley-hills-august-12-1972
INFO:__main__:Getting metadata for https://mubi.com/notebook/posts/interview-with-fritz-lang-beverley-hills-august-12-1972
 92%|█████████▏| 159/172 [04:56<00:13,  1.07s/it]INFO:__main__:Requesting https://www.wired.com/beyond-the-beyond/2018/07/h-g-wells-reviews-movie-metropolis/
INFO:__main__:Getting metadata for https://www.wired.com/beyond-the-beyond/2018/07/h-g-wells-reviews-movie-metropolis/
ERROR:__main__:Could not get metadata for https://www.wired.com/beyond-the-beyond/2018/07/h-g-wells-reviews-movie-metropolis/
Traceback (most recent call last):
  File "../_scripts/crawler/crawler.py", line 94, in _get_site_title_and_description
    description = description[:450] + '...' if len(description) > 450 else description
TypeError: object of type 'NoneType' has no len()
 93%|█████████▎| 160/172 [04:57<00:10,  1.09it/s]INFO:__main__:Requesting https://en.m.wikipedia.org/wiki/Metropolis_(1927_film)
INFO:__main__:Getting metadata for https://en.m.wikipedia.org/wiki/Metropolis_(1927_film)
 94%|█████████▎| 161/172 [04:58<00:12,  1.10s/it]INFO:__main__:Requesting https://en.wikipedia.org/wiki/Contempt_(film)
INFO:__main__:Getting metadata for https://en.wikipedia.org/wiki/Contempt_(film)
 94%|█████████▍| 162/172 [04:59<00:10,  1.04s/it]INFO:__main__:Requesting https://youtu.be/aUs4awmb3-o
INFO:__main__:Getting metadata for https://www.youtube.com/watch?v=aUs4awmb3-o&feature=youtu.be
 95%|█████████▍| 163/172 [05:00<00:09,  1.02s/it]INFO:__main__:Requesting https://youtu.be/9KLR6rteoOU
INFO:__main__:Getting metadata for https://www.youtube.com/watch?v=9KLR6rteoOU&feature=youtu.be
 95%|█████████▌| 164/172 [05:01<00:07,  1.04it/s]INFO:__main__:Requesting https://www.scientificamerican.com/article/the-entertainer/
INFO:__main__:Getting metadata for https://www.scientificamerican.com/article/the-entertainer/
 96%|█████████▌| 165/172 [05:02<00:07,  1.05s/it]INFO:__main__:Requesting https://en.wikipedia.org/wiki/To_Mock_a_Mockingbird
INFO:__main__:Getting metadata for https://en.wikipedia.org/wiki/To_Mock_a_Mockingbird
 97%|█████████▋| 166/172 [05:03<00:05,  1.11it/s]INFO:__main__:Requesting https://amzn.to/2SvmTdX
INFO:__main__:Getting metadata for https://www.amazon.com/Satan-Cantor-Infinity-Mind-Boggling-Puzzles/dp/0679406883/ref=as_li_ss_tl?ie=UTF8&linkCode=sl1&tag=raganwald001-20&linkId=7ed381bd623f585df034022608da5be9&language=en_US
 97%|█████████▋| 167/172 [05:06<00:08,  1.66s/it]INFO:__main__:Requesting https://en.m.wikipedia.org/wiki/Cardinal_number
INFO:__main__:Getting metadata for https://en.m.wikipedia.org/wiki/Cardinal_number
 98%|█████████▊| 168/172 [05:11<00:09,  2.39s/it]INFO:__main__:Requesting http://us.metamath.org/mpegif/canth2.html
 98%|█████████▊| 169/172 [05:11<00:05,  1.73s/it]INFO:__main__:Requesting https://techcrunch.com/2019/02/26/spacex-gets-nasas-approval-to-test-launch-crew-dragon/
ERROR:__main__:Could not reach https://techcrunch.com/2019/02/26/spacex-gets-nasas-approval-to-test-launch-crew-dragon/
Traceback (most recent call last):
  File "/home/travis/virtualenv/python3.6.3/lib/python3.6/site-packages/urllib3/connectionpool.py", line 600, in urlopen
    chunked=chunked)
  File "/home/travis/virtualenv/python3.6.3/lib/python3.6/site-packages/urllib3/connectionpool.py", line 384, in _make_request
    six.raise_from(e, None)
  File "<string>", line 2, in raise_from
  File "/home/travis/virtualenv/python3.6.3/lib/python3.6/site-packages/urllib3/connectionpool.py", line 380, in _make_request
    httplib_response = conn.getresponse()
  File "/opt/python/3.6.3/lib/python3.6/http/client.py", line 1331, in getresponse
    response.begin()
  File "/opt/python/3.6.3/lib/python3.6/http/client.py", line 297, in begin
    version, status, reason = self._read_status()
  File "/opt/python/3.6.3/lib/python3.6/http/client.py", line 266, in _read_status
    raise RemoteDisconnected("Remote end closed connection without"
http.client.RemoteDisconnected: Remote end closed connection without response

During handling of the above exception, another exception occurred:

Traceback (most recent call last):
  File "/home/travis/virtualenv/python3.6.3/lib/python3.6/site-packages/requests/adapters.py", line 449, in send
    timeout=timeout
  File "/home/travis/virtualenv/python3.6.3/lib/python3.6/site-packages/urllib3/connectionpool.py", line 638, in urlopen
    _stacktrace=sys.exc_info()[2])
  File "/home/travis/virtualenv/python3.6.3/lib/python3.6/site-packages/urllib3/util/retry.py", line 367, in increment
    raise six.reraise(type(error), error, _stacktrace)
  File "/home/travis/virtualenv/python3.6.3/lib/python3.6/site-packages/urllib3/packages/six.py", line 685, in reraise
    raise value.with_traceback(tb)
  File "/home/travis/virtualenv/python3.6.3/lib/python3.6/site-packages/urllib3/connectionpool.py", line 600, in urlopen
    chunked=chunked)
  File "/home/travis/virtualenv/python3.6.3/lib/python3.6/site-packages/urllib3/connectionpool.py", line 384, in _make_request
    six.raise_from(e, None)
  File "<string>", line 2, in raise_from
  File "/home/travis/virtualenv/python3.6.3/lib/python3.6/site-packages/urllib3/connectionpool.py", line 380, in _make_request
    httplib_response = conn.getresponse()
  File "/opt/python/3.6.3/lib/python3.6/http/client.py", line 1331, in getresponse
    response.begin()
  File "/opt/python/3.6.3/lib/python3.6/http/client.py", line 297, in begin
    version, status, reason = self._read_status()
  File "/opt/python/3.6.3/lib/python3.6/http/client.py", line 266, in _read_status
    raise RemoteDisconnected("Remote end closed connection without"
urllib3.exceptions.ProtocolError: ('Connection aborted.', RemoteDisconnected('Remote end closed connection without response',))

During handling of the above exception, another exception occurred:

Traceback (most recent call last):
  File "../_scripts/crawler/crawler.py", line 210, in metafy_url
    response = requests.get(url, timeout=6, headers={'User-Agent': 'Mozilla/5.0'})
  File "/home/travis/virtualenv/python3.6.3/lib/python3.6/site-packages/requests/api.py", line 75, in get
    return request('get', url, params=params, **kwargs)
  File "/home/travis/virtualenv/python3.6.3/lib/python3.6/site-packages/requests/api.py", line 60, in request
    return session.request(method=method, url=url, **kwargs)
  File "/home/travis/virtualenv/python3.6.3/lib/python3.6/site-packages/requests/sessions.py", line 533, in request
    resp = self.send(prep, **send_kwargs)
  File "/home/travis/virtualenv/python3.6.3/lib/python3.6/site-packages/requests/sessions.py", line 646, in send
    r = adapter.send(request, **kwargs)
  File "/home/travis/virtualenv/python3.6.3/lib/python3.6/site-packages/requests/adapters.py", line 498, in send
    raise ConnectionError(err, request=request)
requests.exceptions.ConnectionError: ('Connection aborted.', RemoteDisconnected('Remote end closed connection without response',))
 99%|█████████▉| 170/172 [05:11<00:02,  1.25s/it]INFO:__main__:Requesting https://www.nasaspaceflight.com/2019/02/spacex-gains-frr-green-light-dm-1-iss/
INFO:__main__:Getting metadata for https://www.nasaspaceflight.com/2019/02/spacex-gains-frr-green-light-dm-1-iss/
 99%|█████████▉| 171/172 [05:12<00:01,  1.12s/it]INFO:__main__:Requesting https://outline.com/LqnKkg
INFO:__main__:Getting metadata for https://outline.com/LqnKkg
100%|██████████| 172/172 [05:13<00:00,  1.12s/it]
